<?xml version="1.0" ?>
<!-- =================================================================================== -->
<!-- |    This document was autogenerated by xacro from hmc_v2_hand.urdf.xacro         | -->
<!-- |    EDITING THIS FILE BY HAND IS NOT RECOMMENDED                                 | -->
<!-- =================================================================================== -->
<robot name="hmc_v2_hand">
  <link name="base_footprint"/>
  <link name="base_link">
    <inertial>
      <origin rpy="0 0 0" xyz="0.0236 0.0004 0.1132"/>
      <mass value="31.0"/>
      <inertia ixx="0.4482" ixy="0.0007" ixz="0.0283" iyy="0.6592" iyz="0.0027" izz="0.4715"/>
    </inertial>
    <visual>
      <origin rpy="0 0 0" xyz="0 0 0"/>
      <geometry>
        <mesh filename="package://hmc_v2_hand_description/meshes/hmc/lge_driving/base_link.STL"/>
      </geometry>
      <material name="">
        <color rgba="0.79216 0.81961 0.93333 1"/>
      </material>
    </visual>
    <collision>
      <origin rpy="0 0 0" xyz="0 0 0"/>
      <geometry>
        <mesh filename="package://hmc_v2_hand_description/meshes/hmc/lge_driving/base_link.STL"/>
      </geometry>
    </collision>
  </link>
  <joint name="base_link_joint" type="fixed">
    <parent link="base_footprint"/>
    <child link="base_link"/>
    <origin rpy="0 0 0" xyz="0 0 0.085"/>
  </joint>
  <!-- Temp Body Sensors -->
  <link name="rslidar"/>
  <joint name="3d_lidar_joint" type="fixed">
    <parent link="base_link"/>
    <child link="rslidar"/>
    <origin rpy="0 0 0" xyz="0.13 0 1.035"/>
  </joint>
  <link name="camera_link"/>
  <joint name="front_camera_joint" type="fixed">
    <parent link="base_link"/>
    <child link="camera_link"/>
    <origin rpy="0 0.427 0" xyz="0.10 0.025 1.125"/>
  </joint>
  <link name="left_wheel_link">
    <inertial>
      <origin rpy="0 0 0" xyz="-0.0001 0.0000 0.0741"/>
      <mass value="1.0412137835695"/>
      <inertia ixx="0.0018" ixy="0" ixz="0" iyy="0.0032" iyz="0" izz="0.0018"/>
    </inertial>
    <visual>
      <origin rpy="0 0 0" xyz="0 0 0"/>
      <geometry>
        <mesh filename="package://hmc_v2_hand_description/meshes/hmc/lge_driving/left_wheel_link.STL"/>
      </geometry>
      <material name="">
        <color rgba="0.792156862745098 0.819607843137255 0.933333333333333 1"/>
      </material>
    </visual>
    <collision>
      <origin rpy="0 0 0" xyz="0 0 0"/>
      <geometry>
        <mesh filename="package://hmc_v2_hand_description/meshes/hmc/lge_driving/left_wheel_link.STL"/>
      </geometry>
    </collision>
  </link>
  <joint name="left_wheel_joint" type="fixed">
    <origin rpy="-1.5708 0 -0.0020566" xyz="0.010269 0.12673 0.047804"/>
    <parent link="base_link"/>
    <child link="left_wheel_link"/>
  </joint>
  <link name="right_wheel_link">
    <inertial>
      <origin rpy="0 0 0" xyz="0 0 -0.0736"/>
      <mass value="1.0412"/>
      <inertia ixx="0.0018" ixy="0" ixz="0" iyy="0.0032" iyz="0" izz="0.0018"/>
    </inertial>
    <visual>
      <origin rpy="0 0 0" xyz="0 0 0"/>
      <geometry>
        <mesh filename="package://hmc_v2_hand_description/meshes/hmc/lge_driving/right_wheel_link.STL"/>
      </geometry>
      <material name="">
        <color rgba="1 1 1 1"/>
      </material>
    </visual>
    <collision>
      <origin rpy="0 0 0" xyz="0 0 0"/>
      <geometry>
        <mesh filename="package://hmc_v2_hand_description/meshes/hmc/lge_driving/right_wheel_link.STL"/>
      </geometry>
    </collision>
  </link>
  <joint name="right_wheel_joint" type="fixed">
    <origin rpy="-1.5708 0 0" xyz="0.0097457 -0.12777 0.047804"/>
    <parent link="base_link"/>
    <child link="right_wheel_link"/>
  </joint>
  <link name="front_camera_depth_frame"/>
  <link name="front_camera_depth_optical_frame"/>
  <link name="front_camera_color_frame"/>
  <link name="front_camera_color_optical_frame"/>
  <link name="front_camera_infra1_frame"/>
  <link name="front_camera_infra1_optical_frame"/>
  <link name="front_camera_infra2_frame"/>
  <link name="front_camera_infra2_optical_frame"/>
  <joint name="front_camera_depth_joint" type="fixed">
    <parent link="camera_link"/>
    <child link="front_camera_depth_frame"/>
    <origin rpy="0 0 0" xyz="0 0 0"/>
  </joint>
  <joint name="front_camera_depth_optical_joint" type="fixed">
    <parent link="front_camera_depth_frame"/>
    <child link="front_camera_depth_optical_frame"/>
    <origin rpy="-1.57 0 -1.57" xyz="0 0 0 "/>
  </joint>
  <joint name="front_camera_color_joint" type="fixed">
    <parent link="front_camera_depth_frame"/>
    <child link="front_camera_color_frame"/>
    <origin rpy="0 0 0" xyz="0 0 0"/>
  </joint>
  <joint name="front_camera_color_optical_joint" type="fixed">
    <parent link="front_camera_color_frame"/>
    <child link="front_camera_color_optical_frame"/>
    <origin rpy="-1.57 0 -1.57" xyz="0 0 0 "/>
  </joint>
  <joint name="front_camera_infra1_joint" type="fixed">
    <parent link="front_camera_depth_frame"/>
    <child link="front_camera_infra1_frame"/>
    <origin rpy="0 0 0 " xyz="0 0 0 "/>
  </joint>
  <joint name="front_camera_infra1_optical_joint" type="fixed">
    <parent link="front_camera_infra1_frame"/>
    <child link="front_camera_infra1_optical_frame"/>
    <origin rpy="-1.57 0 -1.57" xyz="0 0 0 "/>
  </joint>
  <joint name="front_camera_infra2_joint" type="fixed">
    <parent link="front_camera_depth_frame"/>
    <child link="front_camera_infra2_frame"/>
    <origin rpy="0 0 0" xyz="0 -0.050 0 "/>
  </joint>
  <joint name="front_camera_infra2_optical_joint" type="fixed">
    <parent link="front_camera_infra2_frame"/>
    <child link="front_camera_infra2_optical_frame"/>
    <origin rpy="-1.57 0 -1.57" xyz="0 0 0 "/>
  </joint>
  <!-- I'm D435 Front Cliff camera -->
  <link name="camera_front_cliff_link"/>
  <joint name="camera_front_cliff_joint" type="fixed">
    <parent link="base_link"/>
    <child link="camera_front_cliff_link"/>
    <origin rpy="0 0.48 0" xyz="0.33 0 0.04"/>
  </joint>
  <link name="camera_front_cliff_depth_frame"/>
  <link name="camera_front_cliff_depth_optical_frame"/>
  <link name="camera_front_cliff_color_frame"/>
  <link name="camera_front_cliff_color_optical_frame"/>
  <link name="camera_front_cliff_infra1_frame"/>
  <link name="camera_front_cliff_infra1_optical_frame"/>
  <link name="camera_front_cliff_infra2_frame"/>
  <link name="camera_front_cliff_infra2_optical_frame"/>
  <joint name="camera_front_cliff_depth_joint" type="fixed">
    <parent link="camera_front_cliff_link"/>
    <child link="camera_front_cliff_depth_frame"/>
    <origin rpy="0 0 0" xyz="0 0 0"/>
  </joint>
  <joint name="camera_front_cliff_depth_optical_joint" type="fixed">
    <parent link="camera_front_cliff_depth_frame"/>
    <child link="camera_front_cliff_depth_optical_frame"/>
    <origin rpy="-1.57 0 -1.57" xyz="0 0 0 "/>
  </joint>
  <joint name="camera_front_cliff_color_joint" type="fixed">
    <parent link="camera_front_cliff_depth_frame"/>
    <child link="camera_front_cliff_color_frame"/>
    <origin rpy="0 0 0" xyz="0 0 0"/>
  </joint>
  <joint name="camera_front_cliff_color_optical_joint" type="fixed">
    <parent link="camera_front_cliff_color_frame"/>
    <child link="camera_front_cliff_color_optical_frame"/>
    <origin rpy="-1.57 0 -1.57" xyz="0 0 0 "/>
  </joint>
  <joint name="camera_front_cliff_infra1_joint" type="fixed">
    <parent link="camera_front_cliff_depth_frame"/>
    <child link="camera_front_cliff_infra1_frame"/>
    <origin rpy="0 0 0 " xyz="0 0 0 "/>
  </joint>
  <joint name="camera_front_cliff_infra1_optical_joint" type="fixed">
    <parent link="camera_front_cliff_infra1_frame"/>
    <child link="camera_front_cliff_infra1_optical_frame"/>
    <origin rpy="-1.57 0 -1.57" xyz="0 0 0 "/>
  </joint>
  <joint name="camera_front_cliff_infra2_joint" type="fixed">
    <parent link="camera_front_cliff_depth_frame"/>
    <child link="camera_front_cliff_infra2_frame"/>
    <origin rpy="0 0 0" xyz="0 -0.050 0 "/>
  </joint>
  <joint name="camera_front_cliff_infra2_optical_joint" type="fixed">
    <parent link="camera_front_cliff_infra2_frame"/>
    <child link="camera_front_cliff_infra2_optical_frame"/>
    <origin rpy="-1.57 0 -1.57" xyz="0 0 0 "/>
  </joint>
  <!-- I'm D435 Rear Cliff camera -->
  <link name="rear_cliff_camera_link"/>
  <joint name="rear_cliff_camera_joint" type="fixed">
    <parent link="base_link"/>
    <child link="rear_cliff_camera_link"/>
    <origin rpy="0 0.442 1.57" xyz="-0.35 0 0"/>
  </joint>
  <link name="rear_cliff_camera_depth_frame"/>
  <link name="rear_cliff_camera_depth_optical_frame"/>
  <link name="rear_cliff_camera_color_frame"/>
  <link name="rear_cliff_camera_color_optical_frame"/>
  <link name="rear_cliff_camera_infra1_frame"/>
  <link name="rear_cliff_camera_infra1_optical_frame"/>
  <link name="rear_cliff_camera_infra2_frame"/>
  <link name="rear_cliff_camera_infra2_optical_frame"/>
  <joint name="rear_cliff_camera_depth_joint" type="fixed">
    <parent link="rear_cliff_camera_link"/>
    <child link="rear_cliff_camera_depth_frame"/>
    <origin rpy="0 0 0" xyz="0 0 0"/>
  </joint>
  <joint name="rear_cliff_camera_depth_optical_joint" type="fixed">
    <parent link="rear_cliff_camera_depth_frame"/>
    <child link="rear_cliff_camera_depth_optical_frame"/>
    <origin rpy="-1.57 0 -1.57" xyz="0 0 0 "/>
  </joint>
  <joint name="rear_cliff_camera_color_joint" type="fixed">
    <parent link="rear_cliff_camera_depth_frame"/>
    <child link="rear_cliff_camera_color_frame"/>
    <origin rpy="0 0 0" xyz="0 0 0"/>
  </joint>
  <joint name="rear_cliff_camera_color_optical_joint" type="fixed">
    <parent link="rear_cliff_camera_color_frame"/>
    <child link="rear_cliff_camera_color_optical_frame"/>
    <origin rpy="-1.57 0 -1.57" xyz="0 0 0 "/>
  </joint>
  <joint name="rear_cliff_camera_infra1_joint" type="fixed">
    <parent link="rear_cliff_camera_depth_frame"/>
    <child link="rear_cliff_camera_infra1_frame"/>
    <origin rpy="0 0 0 " xyz="0 0 0 "/>
  </joint>
  <joint name="rear_cliff_camera_infra1_optical_joint" type="fixed">
    <parent link="rear_cliff_camera_infra1_frame"/>
    <child link="rear_cliff_camera_infra1_optical_frame"/>
    <origin rpy="-1.57 0 -1.57" xyz="0 0 0 "/>
  </joint>
  <joint name="rear_cliff_camera_infra2_joint" type="fixed">
    <parent link="rear_cliff_camera_depth_frame"/>
    <child link="rear_cliff_camera_infra2_frame"/>
    <origin rpy="0 0 0" xyz="0 -0.050 0 "/>
  </joint>
  <joint name="rear_cliff_camera_infra2_optical_joint" type="fixed">
    <parent link="rear_cliff_camera_infra2_frame"/>
    <child link="rear_cliff_camera_infra2_optical_frame"/>
    <origin rpy="-1.57 0 -1.57" xyz="0 0 0 "/>
  </joint>
  <link name="body_base_link"/>
  <link name="waist_link_1">
    <inertial>
      <origin rpy="0 0 0" xyz="0.142736534245847 -0.000149905989456311 -0.00356287515423336"/>
      <mass value="1.79225913536589"/>
      <inertia ixx="0.00456218251307419" ixy="3.43432914369734E-07" ixz="5.30349782578929E-06" iyy="0.0210169186055339" iyz="-4.93836257875701E-09" izz="0.0247430714105287"/>
    </inertial>
    <visual>
      <origin rpy="0 0 0" xyz="0 0 0"/>
      <geometry>
        <mesh filename="package://hmc_v2_hand_description/meshes/hmc/v2/waist_link_1.STL"/>
      </geometry>
      <material name="">
        <color rgba="0.792156862745098 0.819607843137255 0.933333333333333 1"/>
      </material>
    </visual>
    <collision>
      <origin rpy="0 0 0" xyz="0 0 0"/>
      <geometry>
        <mesh filename="package://hmc_v2_hand_description/meshes/hmc/v2/waist_link_1.STL"/>
      </geometry>
    </collision>
  </link>
  <joint name="waist_joint_1" type="revolute">
    <origin rpy="-1.5729 -1.5708 0" xyz="0 0 0"/>
    <parent link="body_base_link"/>
    <child link="waist_link_1"/>
    <axis xyz="0 0 1"/>
    <limit effort="100.0" lower="-1.0472" upper="0.0872" velocity="6.2832"/>
  </joint>
  <link name="waist_link_2">
    <inertial>
      <origin rpy="0 0 0" xyz="0.1498 0.0024461 0.005751"/>
      <mass value="1.1731"/>
      <inertia ixx="0.0026377" ixy="-0.00044834" ixz="4.7234E-05" iyy="0.017265" iyz="2.4237E-05" izz="0.019191"/>
    </inertial>
    <visual>
      <origin rpy="0 0 0" xyz="0 0 0"/>
      <geometry>
        <mesh filename="package://hmc_v2_hand_description/meshes/hmc/v2/waist_link_2.STL"/>
      </geometry>
      <material name="">
        <color rgba="0.79216 0.81961 0.93333 1"/>
      </material>
    </visual>
    <collision>
      <origin rpy="0 0 0" xyz="0 0 0"/>
      <geometry>
        <mesh filename="package://hmc_v2_hand_description/meshes/hmc/v2/waist_link_2.STL"/>
      </geometry>
    </collision>
  </link>
  <joint name="waist_joint_2" type="revolute">
    <origin rpy="0.0041133 0 0" xyz="0.29 0 0"/>
    <parent link="waist_link_1"/>
    <child link="waist_link_2"/>
    <axis xyz="0 0 1"/>
    <limit effort="100.0" lower="0.4363" upper="2.0944" velocity="6.2832"/>
  </joint>
  <link name="waist_link_3">
    <inertial>
      <origin rpy="0 0 0" xyz="0.0002 -0.0502 0.0013"/>
      <mass value="1.4321"/>
      <inertia ixx="0.0080" ixy="0" ixz="0" iyy="0.0056" iyz="-0.0001" izz="0.0051"/>
    </inertial>
    <visual>
      <origin rpy="0 0 -1.5708" xyz="0 0 0"/>
      <geometry>
        <mesh filename="package://hmc_v2_hand_description/meshes/hmc/v2/waist_link_3.STL"/>
      </geometry>
      <material name="">
        <color rgba="0.79216 0.81961 0.93333 1"/>
      </material>
    </visual>
    <collision>
      <origin rpy="0 0 -1.5708" xyz="0 0 0"/>
      <geometry>
        <mesh filename="package://hmc_v2_hand_description/meshes/hmc/v2/waist_link_3.STL"/>
      </geometry>
    </collision>
  </link>
  <joint name="waist_joint_3" type="revolute">
    <origin rpy="0 0.0041133 3.1416" xyz="0.33 0 0"/>
    <parent link="waist_link_2"/>
    <child link="waist_link_3"/>
    <axis xyz="0 0 1"/>
    <limit effort="100.0" lower="-1.0472" upper="-0.4363" velocity="6.2832"/>
  </joint>
  <link name="chest_link">
    <inertial>
      <origin rpy="1.5708 0 0" xyz="-4.79142209413594E-06 0.235786071602311 0.0233718266176681"/>
      <mass value="1.37274676723493"/>
      <inertia ixx="0.00588438486435968" ixy="1.66676967015448E-06" ixz="-6.44086497938487E-07" iyy="0.00425927877692745" iyz="-0.000126817279137205" izz="0.00791079789743538"/>
    </inertial>
    <visual>
      <origin rpy="1.5708 0 0" xyz="0 0 0"/>
      <geometry>
        <mesh filename="package://hmc_v2_hand_description/meshes/hmc/v1/chest_link.STL"/>
      </geometry>
      <material name="">
        <color rgba="0.792156862745098 0.819607843137255 0.933333333333333 1"/>
      </material>
    </visual>
    <collision>
      <origin rpy="1.5708 0 0" xyz="0 0 0"/>
      <geometry>
        <mesh filename="package://hmc_v2_hand_description/meshes/hmc/v1/chest_link.STL"/>
      </geometry>
    </collision>
  </link>
  <joint name="waist_joint_4" type="revolute">
    <origin rpy="0 -1.5708 0" xyz="0 0 0"/>
    <parent link="waist_link_3"/>
    <child link="chest_link"/>
    <axis xyz="0 0 1"/>
    <limit effort="100.0" lower="-0.7854" upper="0.7853" velocity="6.2832"/>
  </joint>
  <link name="neck_link">
    <inertial>
      <origin rpy="1.5708 0 0" xyz="-0.00205872530314151 0.04238566701636 1.93081365069403E-05"/>
      <mass value="0.0390494803993089"/>
      <inertia ixx="2.77163309629108E-05" ixy="5.68338577656168E-08" ixz="-4.98283979963023E-09" iyy="2.71364016862964E-05" iyz="-4.18262728637652E-09" izz="2.56997467676319E-05"/>
    </inertial>
    <visual>
      <origin rpy="1.5708 0 0" xyz="0 0 0"/>
      <geometry>
        <mesh filename="package://hmc_v2_hand_description/meshes/hmc/head/neck_link.STL"/>
      </geometry>
      <material name="">
        <color rgba="0.792156862745098 0.819607843137255 0.933333333333333 1"/>
      </material>
    </visual>
    <collision>
      <origin rpy="1.5708 0 0" xyz="0 0 0"/>
      <geometry>
        <mesh filename="package://hmc_v2_hand_description/meshes/hmc/head/neck_link.STL"/>
      </geometry>
    </collision>
  </link>
  <joint name="neck_yaw_joint" type="revolute">
    <origin rpy="0 0 0" xyz="0 0.0155 0.356701305999114"/>
    <parent link="chest_link"/>
    <child link="neck_link"/>
    <axis xyz="0 0 1"/>
    <limit effort="100.0" lower="-1.7453" upper="1.7453" velocity="6.2832"/>
  </joint>
  <link name="head_link">
    <inertial>
      <origin rpy="0 -1.5708 1.5708" xyz="0.00222401369188892 0.0136171325990786 0.0347864514801999"/>
      <mass value="0.212752767421294"/>
      <inertia ixx="0.000732184384251682" ixy="-9.73354657028775E-06" ixz="-2.25868195605443E-06" iyy="0.00117488349525831" iyz="-8.60660486548909E-05" izz="0.000765597881859788"/>
    </inertial>
    <visual>
      <origin rpy="0 -1.5708 1.5708" xyz="0 0 0"/>
      <geometry>
        <mesh filename="package://hmc_v2_hand_description/meshes/hmc/head/head_link.STL"/>
      </geometry>
      <material name="">
        <color rgba="0.792156862745098 0.819607843137255 0.933333333333333 1"/>
      </material>
    </visual>
    <collision>
      <origin rpy="0 -1.5708 1.5708" xyz="0 0 0"/>
      <geometry>
        <mesh filename="package://hmc_v2_hand_description/meshes/hmc/head/head_link.STL"/>
      </geometry>
    </collision>
  </link>
  <joint name="neck_pitch_joint" type="revolute">
    <origin rpy="0 1.5708 0" xyz="0 0 0.072835"/>
    <parent link="neck_link"/>
    <child link="head_link"/>
    <axis xyz="0 0 1"/>
    <limit effort="100.0" lower="-0.1745" upper="0.1745" velocity="6.2832"/>
  </joint>
  <link name="left_link_1">
    <inertial>
      <origin rpy="0 1.5708 1.5708" xyz="0.0604657563309395 0.00261573689447125 -0.00256080558387077"/>
      <mass value="0.16598291492065"/>
      <inertia ixx="0.000252534966687828" ixy="-1.9195828327053E-06" ixz="-2.89734573193127E-05" iyy="0.000267643998703766" iyz="-1.12341857523881E-06" izz="0.000368137981441908"/>
    </inertial>
    <visual>
      <origin rpy="0 1.5708 1.5708" xyz="0 0 0"/>
      <geometry>
        <mesh filename="package://hmc_v2_hand_description/meshes/hmc/v1/left_link_1.STL"/>
      </geometry>
      <material name="">
        <color rgba="0.792156862745098 0.819607843137255 0.933333333333333 1"/>
      </material>
    </visual>
    <collision>
      <origin rpy="0 1.5708 1.5708" xyz="0 0 0"/>
      <geometry>
        <mesh filename="package://hmc_v2_hand_description/meshes/hmc/v1/left_link_1.STL"/>
      </geometry>
    </collision>
  </link>
  <joint name="left_joint_1" type="revolute">
    <origin rpy="0 -1.5708 0" xyz="0.10299 0 0.298"/>
    <parent link="chest_link"/>
    <child link="left_link_1"/>
    <axis xyz="0 0 1"/>
    <limit effort="100.0" lower="-0.5236" upper="3.1416" velocity="6.2832"/>
  </joint>
  <link name="left_link_2">
    <inertial>
      <origin rpy="0 0 -1.5708" xyz="-0.000186343043321491 -0.0197952570910309 0.00296544454445556"/>
      <mass value="0.127994559619005"/>
      <inertia ixx="0.000190775991335297" ixy="-2.23701897794492E-08" ixz="1.05874744410057E-08" iyy="0.000102868681741429" iyz="-8.36218367771545E-07" izz="0.000180614095529402"/>
    </inertial>
    <visual>
      <origin rpy="0 0 -1.5708" xyz="0 0 0"/>
      <geometry>
        <mesh filename="package://hmc_v2_hand_description/meshes/hmc/v1/left_link_2.STL"/>
      </geometry>
      <material name="">
        <color rgba="0.792156862745098 0.819607843137255 0.933333333333333 1"/>
      </material>
    </visual>
    <collision>
      <origin rpy="0 0 -1.5708" xyz="0 0 0"/>
      <geometry>
        <mesh filename="package://hmc_v2_hand_description/meshes/hmc/v1/left_link_2.STL"/>
      </geometry>
    </collision>
  </link>
  <joint name="left_joint_2" type="revolute">
    <origin rpy="1.5708 0 0" xyz="0 0 -0.097012510229178"/>
    <parent link="left_link_1"/>
    <child link="left_link_2"/>
    <axis xyz="0 0 1"/>
    <limit effort="100.0" lower="0.0" upper="3.1416" velocity="6.2832"/>
  </joint>
  <link name="left_link_3">
    <inertial>
      <origin rpy="-1.5708 0 -1.5708" xyz="0.000101865630815906 -0.126715744092575 -9.15575459772E-05"/>
      <mass value="0.300844027885635"/>
      <inertia ixx="0.00188786281914134" ixy="-7.40742684828974E-06" ixz="1.41252321923668E-06" iyy="0.000258869709032676" iyz="-8.27431157756213E-06" izz="0.00173806112747642"/>
    </inertial>
    <visual>
      <origin rpy="-1.5708 0 -1.5708" xyz="0 0 0"/>
      <geometry>
        <mesh filename="package://hmc_v2_hand_description/meshes/hmc/v1/left_link_3.STL"/>
      </geometry>
      <material name="">
        <color rgba="0.792156862745098 0.819607843137255 0.933333333333333 1"/>
      </material>
    </visual>
    <collision>
      <origin rpy="-1.5708 0 -1.5708" xyz="0 0 0"/>
      <geometry>
        <mesh filename="package://hmc_v2_hand_description/meshes/hmc/v1/left_link_3.STL"/>
      </geometry>
    </collision>
  </link>
  <joint name="left_joint_3" type="revolute">
    <origin rpy="0 -1.5708 0" xyz="-0.0694946863134078 0 0"/>
    <parent link="left_link_2"/>
    <child link="left_link_3"/>
    <axis xyz="0 0 1"/>
    <limit effort="100.0" lower="-3.1416" upper="3.1416" velocity="6.2832"/>
  </joint>
  <link name="left_link_4">
    <inertial>
      <origin rpy="0 1.5708 0" xyz="-0.000851194247093678 -0.052944192540277 -0.00661459782862343"/>
      <mass value="0.211903098783576"/>
      <inertia ixx="0.000573575546843407" ixy="2.31795771639076E-06" ixz="3.36917296538495E-07" iyy="0.000150860810741421" iyz="-3.16792383430038E-05" izz="0.000475510988036102"/>
    </inertial>
    <visual>
      <origin rpy="0 1.5708 0" xyz="0 0 0"/>
      <geometry>
        <mesh filename="package://hmc_v2_hand_description/meshes/hmc/v1/left_link_4.STL"/>
      </geometry>
      <material name="">
        <color rgba="0.792156862745098 0.819607843137255 0.933333333333333 1"/>
      </material>
    </visual>
    <collision>
      <origin rpy="0 1.5708 0" xyz="0 0 0"/>
      <geometry>
        <mesh filename="package://hmc_v2_hand_description/meshes/hmc/v1/left_link_4.STL"/>
      </geometry>
    </collision>
  </link>
  <joint name="left_joint_4" type="revolute">
    <origin rpy="-1.5708 0 0" xyz="0.00999999994437432 0 0.230505015985369 "/>
    <parent link="left_link_3"/>
    <child link="left_link_4"/>
    <axis xyz="0 0 1"/>
    <limit effort="100.0" lower="0.0" upper="2.3562" velocity="6.2832"/>
  </joint>
  <link name="left_link_5">
    <inertial>
      <origin rpy="-1.5708 0 -1.5708" xyz="-0.000967717343438895 -0.0493037769603948 -3.68522386358511E-05"/>
      <mass value="0.12882916793801"/>
      <inertia ixx="0.000105542421097612" ixy="-8.01676271522041E-06" ixz="-3.33666791255762E-08" iyy="0.000113840553856197" iyz="8.49906450517369E-07" izz="0.000183643214967315"/>
    </inertial>
    <visual>
      <origin rpy="-1.5708 0 -1.5708" xyz="0 0 0"/>
      <geometry>
        <mesh filename="package://hmc_v2_hand_description/meshes/hmc/v1/left_link_5.STL"/>
      </geometry>
      <material name="">
        <color rgba="0.792156862745098 0.819607843137255 0.933333333333333 1"/>
      </material>
    </visual>
    <collision>
      <origin rpy="-1.5708 0 -1.5708" xyz="0 0 0"/>
      <geometry>
        <mesh filename="package://hmc_v2_hand_description/meshes/hmc/v1/left_link_5.STL"/>
      </geometry>
    </collision>
  </link>
  <joint name="left_joint_5" type="revolute">
    <origin rpy="1.5708 0 0" xyz="-0.0099999999541513 -0.128994989295394 0"/>
    <parent link="left_link_4"/>
    <child link="left_link_5"/>
    <axis xyz="0 0 1"/>
    <limit effort="100.0" lower="-2.5307" upper="2.5307" velocity="6.2832"/>
  </joint>
  <link name="left_link_6">
    <inertial>
      <origin rpy="0 0 0" xyz="0.000169920486062319 -0.0263042004983295 -0.000145071047688017"/>
      <mass value="0.105951150017535"/>
      <inertia ixx="0.000172989671152769" ixy="9.10316092305352E-07" ixz="1.1580205630234E-06" iyy="9.15293558324925E-05" iyz="-2.14257569884614E-06" izz="0.000205944876188786"/>
    </inertial>
    <visual>
      <origin rpy="0 1.5708 0" xyz="0 0 0"/>
      <geometry>
        <mesh filename="package://hmc_v2_hand_description/meshes/hmc/v1/left_link_6.STL"/>
      </geometry>
      <material name="">
        <color rgba="0.792156862745098 0.819607843137255 0.933333333333333 1"/>
      </material>
    </visual>
    <collision>
      <origin rpy="0 0 0" xyz="0 0 0"/>
      <geometry>
        <mesh filename="package://hmc_v2_hand_description/meshes/hmc/v1/left_link_6.STL"/>
      </geometry>
    </collision>
  </link>
  <joint name="left_joint_6" type="revolute">
    <origin rpy="-1.5708 0 0" xyz="0 0 0.0900050107058747"/>
    <parent link="left_link_5"/>
    <child link="left_link_6"/>
    <axis xyz="0 0 1"/>
    <limit effort="100.0" lower="-1.2217" upper="1.2217" velocity="6.2832"/>
  </joint>
  <link name="left_link_7">
    <inertial>
      <origin rpy="0 0 0" xyz="0.014843832864763 -0.0464780444497426 0.00742849682973754"/>
      <mass value="0.105479725097714"/>
      <inertia ixx="5.94858933107926E-05" ixy="1.45669701064987E-06" ixz="-5.08762465205573E-06" iyy="6.66194811208462E-05" iyz="-5.17353675780145E-07" izz="8.33467795747027E-05"/>
    </inertial>
    <visual>
      <origin rpy="0 3.1416 0" xyz="0 0 0"/>
      <geometry>
        <mesh filename="package://hmc_v2_hand_description/meshes/hmc/v1/left_link_7.STL"/>
      </geometry>
      <material name="">
        <color rgba="0.792156862745098 0.819607843137255 0.933333333333333 1"/>
      </material>
    </visual>
    <collision>
      <origin rpy="0 3.1416 0" xyz="0 0 0"/>
      <geometry>
        <mesh filename="package://hmc_v2_hand_description/meshes/hmc/v1/left_link_7.STL"/>
      </geometry>
    </collision>
  </link>
  <joint name="left_joint_7" type="revolute">
    <origin rpy="0 1.5708 0" xyz="0 -0.0559999999999951 0"/>
    <parent link="left_link_6"/>
    <child link="left_link_7"/>
    <axis xyz="0 0 1"/>
    <limit effort="100.0" lower="-1.2217" upper="1.2217" velocity="6.2832"/>
  </joint>
  <link name="right_link_1">
    <inertial>
      <origin rpy="0 1.5708 -1.5708" xyz="-0.0604653142914313 0.00261415333446191 -0.00256883939585017"/>
      <mass value="0.166037272200226"/>
      <inertia ixx="0.000252426209610871" ixy="1.96353463518388E-06" ixz="2.89324696755189E-05" iyy="0.000267614452458133" iyz="-1.02342773497771E-06" izz="0.000368012329704678"/>
    </inertial>
    <visual>
      <origin rpy="0 1.5708 -1.5708" xyz="0 0 0"/>
      <geometry>
        <mesh filename="package://hmc_v2_hand_description/meshes/hmc/v1/right_link_1.STL"/>
      </geometry>
      <material name="">
        <color rgba="0.792156862745098 0.819607843137255 0.933333333333333 1"/>
      </material>
    </visual>
    <collision>
      <origin rpy="0 1.5708 -1.5708" xyz="0 0 0"/>
      <geometry>
        <mesh filename="package://hmc_v2_hand_description/meshes/hmc/v1/right_link_1.STL"/>
      </geometry>
    </collision>
  </link>
  <joint name="right_joint_1" type="revolute">
    <origin rpy="0 -1.5708 0" xyz="-0.10298746867529 0 0.297999992867471"/>
    <parent link="chest_link"/>
    <child link="right_link_1"/>
    <axis xyz="0 0 1"/>
    <limit effort="100.0" lower="-0.5236" upper="3.1416" velocity="6.2832"/>
  </joint>
  <link name="right_link_2">
    <inertial>
      <origin rpy="0 0 -1.5708" xyz="0.000185930315096727 -0.0197953420826213 0.00297024960300678"/>
      <mass value="0.127994875196873"/>
      <inertia ixx="0.000190776337197258" ixy="2.00260765418897E-08" ixz="-2.08802309886657E-08" iyy="0.000102866581401637" iyz="-8.34949059297448E-07" izz="0.000180614095514762"/>
    </inertial>
    <visual>
      <origin rpy="0 0 -1.5708" xyz="0 0 0"/>
      <geometry>
        <mesh filename="package://hmc_v2_hand_description/meshes/hmc/v1/right_link_2.STL"/>
      </geometry>
      <material name="">
        <color rgba="0.792156862745098 0.819607843137255 0.933333333333333 1"/>
      </material>
    </visual>
    <collision>
      <origin rpy="0 0 -1.5708" xyz="0 0 0"/>
      <geometry>
        <mesh filename="package://hmc_v2_hand_description/meshes/hmc/v1/right_link_2.STL"/>
      </geometry>
    </collision>
  </link>
  <joint name="right_joint_2" type="revolute">
    <origin rpy="-1.5708 0 0" xyz="0 0 0.09701253132465"/>
    <parent link="right_link_1"/>
    <child link="right_link_2"/>
    <axis xyz="0 0 1"/>
    <limit effort="100.0" lower="0.0" upper="3.1416" velocity="6.2832"/>
  </joint>
  <link name="right_link_3">
    <inertial>
      <origin rpy="1.5708 0 1.5708" xyz="-0.000100237273355092 -0.126716449153423 -9.19140141552796E-05"/>
      <mass value="0.300842364584131"/>
      <inertia ixx="0.00188782027047092" ixy="7.41682924968214E-06" ixz="-1.37468404624646E-06" iyy="0.000258854164194295" iyz="-8.21792279839749E-06" izz="0.00173805944369958"/>
    </inertial>
    <visual>
      <origin rpy="1.5708 0 1.5708" xyz="0 0 0"/>
      <geometry>
        <mesh filename="package://hmc_v2_hand_description/meshes/hmc/v1/right_link_3.STL"/>
      </geometry>
      <material name="">
        <color rgba="0.792156862745098 0.819607843137255 0.933333333333333 1"/>
      </material>
    </visual>
    <collision>
      <origin rpy="1.5708 0 1.5708" xyz="0 0 0"/>
      <geometry>
        <mesh filename="package://hmc_v2_hand_description/meshes/hmc/v1/right_link_3.STL"/>
      </geometry>
    </collision>
  </link>
  <joint name="right_joint_3" type="revolute">
    <origin rpy="0 1.5708 0" xyz="-0.0694701720166495 0 0"/>
    <parent link="right_link_2"/>
    <child link="right_link_3"/>
    <axis xyz="0 0 1"/>
    <limit effort="100.0" lower="-3.1416" upper="3.1416" velocity="6.2832"/>
  </joint>
  <link name="right_link_4">
    <inertial>
      <origin rpy="0 1.5708 0" xyz="0.000847057152808833 -0.0529435826831843 -0.00661445748962435"/>
      <mass value="0.211903370376299"/>
      <inertia ixx="0.000573592194790823" ixy="-2.32397440160579E-06" ixz="-3.53464477349771E-07" iyy="0.000150850980631207" iyz="-3.168729410461E-05" izz="0.000475538331226226"/>
    </inertial>
    <visual>
      <origin rpy="0 1.5708 0" xyz="0 0 0"/>
      <geometry>
        <mesh filename="package://hmc_v2_hand_description/meshes/hmc/v1/right_link_4.STL"/>
      </geometry>
      <material name="">
        <color rgba="0.792156862745098 0.819607843137255 0.933333333333333 1"/>
      </material>
    </visual>
    <collision>
      <origin rpy="0 1.5708 0" xyz="0 0 0"/>
      <geometry>
        <mesh filename="package://hmc_v2_hand_description/meshes/hmc/v1/right_link_4.STL"/>
      </geometry>
    </collision>
  </link>
  <joint name="right_joint_4" type="revolute">
    <origin rpy="1.5708 0 0" xyz="0.00999824065185791 0 -0.230505828376835"/>
    <parent link="right_link_3"/>
    <child link="right_link_4"/>
    <axis xyz="0 0 1"/>
    <limit effort="100.0" lower="0.0" upper="2.3562" velocity="6.2832"/>
  </joint>
  <link name="right_link_5">
    <inertial>
      <origin rpy="1.5708 0 1.5708" xyz="0.000965662353110797 -0.0493031982172842 -3.82933857399903E-05"/>
      <mass value="0.128841933824236"/>
      <inertia ixx="0.000105544605493939" ixy="8.02261465066007E-06" ixz="2.71934363459589E-08" iyy="0.000113848043582788" iyz="8.50039344274095E-07" izz="0.000183652743237793"/>
    </inertial>
    <visual>
      <origin rpy="1.5708 0 1.5708" xyz="0 0 0"/>
      <geometry>
        <mesh filename="package://hmc_v2_hand_description/meshes/hmc/v1/right_link_5.STL"/>
      </geometry>
      <material name="">
        <color rgba="0.792156862745098 0.819607843137255 0.933333333333333 1"/>
      </material>
    </visual>
    <collision>
      <origin rpy="1.5708 0 1.5708" xyz="0 0 0"/>
      <geometry>
        <mesh filename="package://hmc_v2_hand_description/meshes/hmc/v1/right_link_5.STL"/>
      </geometry>
    </collision>
  </link>
  <joint name="right_joint_5" type="revolute">
    <origin rpy="-1.5708 0 0" xyz="-0.00999999981801948 -0.128994707660358 0"/>
    <parent link="right_link_4"/>
    <child link="right_link_5"/>
    <axis xyz="0 0 1"/>
    <limit effort="100.0" lower="-2.5307" upper="2.5307" velocity="6.2832"/>
  </joint>
  <link name="right_link_6">
    <inertial>
      <origin rpy="0 1.5708 0" xyz="-0.000172914519763839 -0.0263050462804398 -0.000145419200298307"/>
      <mass value="0.105952942191506"/>
      <inertia ixx="0.000172984429717537" ixy="-9.10648353341905E-07" ixz="-1.15699579544942E-06" iyy="9.15303665517323E-05" iyz="-2.14027648849235E-06" izz="0.000205939848399399"/>
    </inertial>
    <visual>
      <origin rpy="0 1.5708 0" xyz="0 0 0"/>
      <geometry>
        <mesh filename="package://hmc_v2_hand_description/meshes/hmc/v1/right_link_6.STL"/>
      </geometry>
      <material name="">
        <color rgba="0.792156862745098 0.819607843137255 0.933333333333333 1"/>
      </material>
    </visual>
    <collision>
      <origin rpy="0 1.5708 0" xyz="0 0 0"/>
      <geometry>
        <mesh filename="package://hmc_v2_hand_description/meshes/hmc/v1/right_link_6.STL"/>
      </geometry>
    </collision>
  </link>
  <joint name="right_joint_6" type="revolute">
    <origin rpy="1.5708 0 0" xyz="0 0 -0.0900049959570584"/>
    <parent link="right_link_5"/>
    <child link="right_link_6"/>
    <axis xyz="0 0 1"/>
    <limit effort="100.0" lower="-1.2217" upper="1.2217" velocity="6.2832"/>
  </joint>
  <link name="right_link_7">
    <inertial>
      <origin rpy="0 3.1416 0" xyz="-0.0148392076258777 -0.0464754116850403 0.00742965912518337"/>
      <mass value="0.105501402119207"/>
      <inertia ixx="5.94941433951913E-05" ixy="-1.45437382510908E-06" ixz="5.07670562632049E-06" iyy="6.66463005651119E-05" iyz="-5.19001307240556E-07" izz="8.33782163738634E-05"/>
    </inertial>
    <visual>
      <origin rpy="0 0 0" xyz="0 0 0"/>
      <geometry>
        <mesh filename="package://hmc_v2_hand_description/meshes/hmc/v1/right_link_7.STL"/>
      </geometry>
      <material name="">
        <color rgba="0.792156862745098 0.819607843137255 0.933333333333333 1"/>
      </material>
    </visual>
    <collision>
      <origin rpy="0 0 0" xyz="0 0 0"/>
      <geometry>
        <mesh filename="package://hmc_v2_hand_description/meshes/hmc/v1/right_link_7.STL"/>
      </geometry>
    </collision>
  </link>
  <joint name="right_joint_7" type="revolute">
    <origin rpy="0 -1.5708 0" xyz="0 -0.0559999999999981 0"/>
    <parent link="right_link_6"/>
    <child link="right_link_7"/>
    <axis xyz="0 0 1"/>
    <limit effort="100.0" lower="-1.2217" upper="1.2217" velocity="6.2832"/>
  </joint>
  <link name="left_tool_base_link"/>
  <link name="right_tool_base_link"/>
  <joint name="left_tool_base_link_joint" type="fixed">
    <parent link="left_link_7"/>
    <child link="left_tool_base_link"/>
    <origin rpy="1.5708 3.1416 0" xyz="0 -0.071 0"/>
  </joint>
  <joint name="right_tool_base_link_joint" type="fixed">
    <parent link="right_link_7"/>
    <child link="right_tool_base_link"/>
    <origin rpy="-1.5708 0 -3.1416" xyz="0 -0.071 0"/>
  </joint>
  <!-- chest sensors -->
  <link name="chest_lidar"/>
  <joint name="chest_lidar_joint" type="fixed">
    <parent link="chest_link"/>
    <child link="chest_lidar"/>
    <origin rpy="-1.5708 0 3.1416" xyz="0 -0.13 0.21"/>
  </joint>
  <link name="chest_camera"/>
  <joint name="chest_camera_joint" type="fixed">
    <parent link="chest_link"/>
    <child link="chest_camera"/>
    <origin rpy="-2.0 0 3.1416" xyz="-0.025 -0.10 0.3"/>
  </joint>
  <link name="left_hand_base_link">
    <inertial>
      <origin rpy="0 0 0" xyz="-0.00161046540703813 5.39231302579387E-05 0.0560943804884023"/>
      <mass value="0.114844256740337"/>
      <inertia ixx="0.000157741930579527" ixy="-1.16564183226397E-07" ixz="3.43324969543446E-06" iyy="8.54118913647782E-05" iyz="3.26212690752232E-06" izz="8.6563542843708E-05"/>
    </inertial>
    <visual>
      <origin rpy="0 0 0" xyz="0 0 0"/>
      <geometry>
        <mesh filename="package://hmc_v2_hand_description/meshes/agibot_o12_t2_hand/left/left_hand_base_link.STL"/>
      </geometry>
      <material name="">
        <color rgba="0.792156862745098 0.819607843137255 0.933333333333333 1"/>
      </material>
    </visual>
    <collision>
      <origin rpy="0 0 0" xyz="0 0 0"/>
      <geometry>
        <mesh filename="package://hmc_v2_hand_description/meshes/agibot_o12_t2_hand/left/left_hand_base_link.STL"/>
      </geometry>
    </collision>
  </link>
  <link name="left_thumb_metacarpals_base1">
    <inertial>
      <origin rpy="0 0 0" xyz="0.0128313740207018 0.000678738882395103 -6.35819005504745E-05"/>
      <mass value="0.00393646023590197"/>
      <inertia ixx="5.66341789910244E-07" ixy="-2.9983411196748E-08" ixz="-8.53073936132261E-10" iyy="2.92952202949426E-07" iyz="-1.91258689248169E-08" izz="6.19997558364507E-07"/>
    </inertial>
    <visual>
      <origin rpy="0 0 0" xyz="0 0 0"/>
      <geometry>
        <mesh filename="package://hmc_v2_hand_description/meshes/agibot_o12_t2_hand/left/left_thumb_metacarpals_base1.STL"/>
      </geometry>
      <material name="">
        <color rgba="1 1 1 1"/>
      </material>
    </visual>
    <collision>
      <origin rpy="0 0 0" xyz="0 0 0"/>
      <geometry>
        <mesh filename="package://hmc_v2_hand_description/meshes/agibot_o12_t2_hand/left/left_thumb_metacarpals_base1.STL"/>
      </geometry>
    </collision>
  </link>
  <joint name="left_thumb_cmc_roll" type="revolute">
    <origin rpy="0 0 0" xyz="-0.0075211 -0.022278 0.04025"/>
    <parent link="left_hand_base_link"/>
    <child link="left_thumb_metacarpals_base1"/>
    <axis xyz="-1 0 0"/>
    <limit effort="100" lower="-0.2930" upper="0.6489" velocity="1"/>
  </joint>
  <link name="left_thumb_metacarpals_base2">
    <inertial>
      <origin rpy="0 0 0" xyz="0.0058163964840658 -0.00635112672429271 0.00301818029633513"/>
      <mass value="0.00171679371228901"/>
      <inertia ixx="1.18470417835418E-07" ixy="4.21491774967571E-08" ixz="-1.05146545577021E-08" iyy="1.14930696459633E-07" iyz="1.74179531150921E-08" izz="9.67476258420216E-08"/>
    </inertial>
    <visual>
      <origin rpy="0 0 0" xyz="0 0 0"/>
      <geometry>
        <mesh filename="package://hmc_v2_hand_description/meshes/agibot_o12_t2_hand/left/left_thumb_metacarpals_base2.STL"/>
      </geometry>
      <material name="">
        <color rgba="1 1 1 1"/>
      </material>
    </visual>
    <collision>
      <origin rpy="0 0 0" xyz="0 0 0"/>
      <geometry>
        <mesh filename="package://hmc_v2_hand_description/meshes/agibot_o12_t2_hand/left/left_thumb_metacarpals_base2.STL"/>
      </geometry>
    </collision>
  </link>
  <joint name="left_thumb_cmc_yaw" type="revolute">
    <origin rpy="0 0 0" xyz="0.035071 -0.0033014 0"/>
    <parent link="left_thumb_metacarpals_base1"/>
    <child link="left_thumb_metacarpals_base2"/>
    <axis xyz="0 0 1"/>
    <limit effort="100" lower="0" upper="1.3868" velocity="1"/>
  </joint>
  <link name="left_thumb_metacarpals">
    <inertial>
      <origin rpy="0 0 0" xyz="0.0038585 -0.00018025 0.026273"/>
      <mass value="0.017091"/>
      <inertia ixx="6.6313E-06" ixy="8.9032E-09" ixz="-3.4033E-07" iyy="8.0389E-06" iyz="-1.3648E-08" izz="1.8308E-06"/>
    </inertial>
    <visual>
      <origin rpy="0 0 0" xyz="0 0 0"/>
      <geometry>
        <mesh filename="package://hmc_v2_hand_description/meshes/agibot_o12_t2_hand/left/left_thumb_metacarpals.STL"/>
      </geometry>
      <material name="">
        <color rgba="1 1 1 1"/>
      </material>
    </visual>
    <collision>
      <origin rpy="0 0 0" xyz="0 0 0"/>
      <geometry>
        <mesh filename="package://hmc_v2_hand_description/meshes/agibot_o12_t2_hand/left/left_thumb_metacarpals.STL"/>
      </geometry>
    </collision>
  </link>
  <joint name="left_thumb_cmc_pitch" type="revolute">
    <origin rpy="0 -0.92529 2.3508" xyz="0.01613 -0.016305 0.0068611"/>
    <parent link="left_thumb_metacarpals_base2"/>
    <child link="left_thumb_metacarpals"/>
    <axis xyz="0 1 0"/>
    <limit effort="100" lower="0" upper="0.8268" velocity="1"/>
  </joint>
  <link name="left_thumb_proximal">
    <inertial>
      <origin rpy="0 0 0" xyz="-0.00245650869112198 0.00186600341761619 0.013443158548372"/>
      <mass value="0.00522967384448073"/>
      <inertia ixx="4.4882364883548E-07" ixy="-9.70033971351608E-10" ixz="-7.97636981715347E-08" iyy="6.21157859198411E-07" iyz="-3.64690905670397E-09" izz="2.25091891426767E-07"/>
    </inertial>
    <visual>
      <origin rpy="0 0 0" xyz="0 0 0"/>
      <geometry>
        <mesh filename="package://hmc_v2_hand_description/meshes/agibot_o12_t2_hand/left/left_thumb_proximal.STL"/>
      </geometry>
      <material name="">
        <color rgba="0.792156862745098 0.819607843137255 0.933333333333333 1"/>
      </material>
    </visual>
    <collision>
      <origin rpy="0 0 0" xyz="0 0 0"/>
      <geometry>
        <mesh filename="package://hmc_v2_hand_description/meshes/agibot_o12_t2_hand/left/left_thumb_proximal.STL"/>
      </geometry>
    </collision>
  </link>
  <joint name="left_thumb_mcp" type="revolute">
    <origin rpy="0 0 0" xyz="0.0081645 -0.00155 0.055634"/>
    <parent link="left_thumb_metacarpals"/>
    <child link="left_thumb_proximal"/>
    <axis xyz="0 1 0"/>
    <limit effort="100" lower="0" upper="1.2908" velocity="1"/>
  </joint>
  <link name="left_thumb_distal">
    <inertial>
      <origin rpy="0 0 0" xyz="0.000307410958653317 2.07011111937551E-05 0.00928986767954124"/>
      <mass value="0.00521800678366716"/>
      <inertia ixx="3.57694191306713E-07" ixy="-7.42469621090903E-11" ixz="7.81638833861074E-08" iyy="3.45473369597084E-07" iyz="3.05956318690256E-10" izz="2.66044552225899E-07"/>
    </inertial>
    <visual>
      <origin rpy="0 0 0" xyz="0 0 0"/>
      <geometry>
        <mesh filename="package://hmc_v2_hand_description/meshes/agibot_o12_t2_hand/left/left_thumb_distal.STL"/>
      </geometry>
      <material name="">
        <color rgba="0.796078431372549 0.823529411764706 0.937254901960784 1"/>
      </material>
    </visual>
    <collision>
      <origin rpy="0 0 0" xyz="0 0 0"/>
      <geometry>
        <mesh filename="package://hmc_v2_hand_description/meshes/agibot_o12_t2_hand/left/left_thumb_distal.STL"/>
      </geometry>
    </collision>
  </link>
  <joint name="left_thumb_ip" type="revolute">
    <origin rpy="0 0 0" xyz="-0.0015545 0.0015 0.034528"/>
    <parent link="left_thumb_proximal"/>
    <child link="left_thumb_distal"/>
    <axis xyz="0 1 0"/>
    <limit effort="100" lower="0" upper="1.3781" velocity="1"/>
    <mimic joint="left_thumb_mcp" multiplier="1" offset="0"/>
  </joint>
  <link name="left_thumb_Virtual_Point">
    <inertial>
      <origin rpy="0 0 0" xyz="-0.000184328758149471 -4.99935356591656E-05 -3.91589699965667E-05"/>
      <mass value="5.23598775598299E-07"/>
      <inertia ixx="5.23598775598299E-14" ixy="5.93366978803555E-31" ixz="-1.57772181044202E-30" iyy="5.23598775598299E-14" iyz="-2.50003687143053E-30" izz="5.23598775598299E-14"/>
    </inertial>
    <visual>
      <origin rpy="0 0 0" xyz="0 0 0"/>
      <geometry>
        <mesh filename="package://hmc_v2_hand_description/meshes/agibot_o12_t2_hand/left/left_thumb_Virtual_Point.STL"/>
      </geometry>
      <material name="">
        <color rgba="1 1 1 1"/>
      </material>
    </visual>
    <collision>
      <origin rpy="0 0 0" xyz="0 0 0"/>
      <geometry>
        <mesh filename="package://hmc_v2_hand_description/meshes/agibot_o12_t2_hand/left/left_thumb_Virtual_Point.STL"/>
      </geometry>
    </collision>
  </link>
  <joint name="left_thumb_Virtual_Point-none" type="fixed">
    <origin rpy="0 0 0" xyz="-0.00661 5E-05 0.031568"/>
    <parent link="left_thumb_distal"/>
    <child link="left_thumb_Virtual_Point"/>
    <axis xyz="0 0 0"/>
  </joint>
  <link name="left_index_metacarpals">
    <inertial>
      <origin rpy="0 0 0" xyz="0.00151344006390744 -5.44751780837127E-09 0.00199999391249993"/>
      <mass value="0.00107972492721203"/>
      <inertia ixx="3.54851849057179E-08" ixy="-9.75920143282609E-16" ixz="-2.88674570648891E-09" iyy="2.11264180975032E-08" iyz="-1.69297340759031E-14" izz="3.63609571557396E-08"/>
    </inertial>
    <visual>
      <origin rpy="0 0 0" xyz="0 0 0"/>
      <geometry>
        <mesh filename="package://hmc_v2_hand_description/meshes/agibot_o12_t2_hand/left/left_index_metacarpals.STL"/>
      </geometry>
      <material name="">
        <color rgba="0.792156862745098 0.819607843137255 0.933333333333333 1"/>
      </material>
    </visual>
    <collision>
      <origin rpy="0 0 0" xyz="0 0 0"/>
      <geometry>
        <mesh filename="package://hmc_v2_hand_description/meshes/agibot_o12_t2_hand/left/left_index_metacarpals.STL"/>
      </geometry>
    </collision>
  </link>
  <joint name="left_index_mcp_roll" type="revolute">
    <origin rpy="0 0 0" xyz="-0.0071994 -0.030778 0.11945"/>
    <parent link="left_hand_base_link"/>
    <child link="left_index_metacarpals"/>
    <axis xyz="-1 0 0"/>
    <limit effort="100" lower="-0.2616" upper="0.2616" velocity="1"/>
  </joint>
  <link name="left_index_proximal">
    <inertial>
      <origin rpy="0 0 0" xyz="-0.00115064868057897 -2.08320532571957E-05 0.0212647838486794"/>
      <mass value="0.00477960256059446"/>
      <inertia ixx="5.44834008350545E-07" ixy="-9.03598899419747E-11" ixz="1.65895348406321E-08" iyy="5.41641327287791E-07" iyz="-2.50114390616641E-10" izz="1.75595647730841E-07"/>
    </inertial>
    <visual>
      <origin rpy="0 0 0" xyz="0 0 0"/>
      <geometry>
        <mesh filename="package://hmc_v2_hand_description/meshes/agibot_o12_t2_hand/left/left_index_proximal.STL"/>
      </geometry>
      <material name="">
        <color rgba="1 1 1 1"/>
      </material>
    </visual>
    <collision>
      <origin rpy="0 0 0" xyz="0 0 0"/>
      <geometry>
        <mesh filename="package://hmc_v2_hand_description/meshes/agibot_o12_t2_hand/left/left_index_proximal.STL"/>
      </geometry>
    </collision>
  </link>
  <joint name="left_index_mcp_pitch" type="revolute">
    <origin rpy="0 0 0" xyz="0.0073692 0 -9.4985E-05"/>
    <parent link="left_index_metacarpals"/>
    <child link="left_index_proximal"/>
    <axis xyz="0 1 0"/>
    <limit effort="100" lower="0" upper="1.3519" velocity="1"/>
  </joint>
  <link name="left_index_middle">
    <inertial>
      <origin rpy="0 0 0" xyz="0.000582799122903887 -1.66622418459189E-05 0.013441904734998"/>
      <mass value="0.00270775197321639"/>
      <inertia ixx="2.25567814590075E-07" ixy="4.76662842477137E-12" ixz="5.19478039422153E-09" iyy="1.61875482546986E-07" iyz="-8.95325679002794E-12" izz="1.17900381226969E-07"/>
    </inertial>
    <visual>
      <origin rpy="0 0 0" xyz="0 0 0"/>
      <geometry>
        <mesh filename="package://hmc_v2_hand_description/meshes/agibot_o12_t2_hand/left/left_index_middle.STL"/>
      </geometry>
      <material name="">
        <color rgba="0 0 0 1"/>
      </material>
    </visual>
    <collision>
      <origin rpy="0 0 0" xyz="0 0 0"/>
      <geometry>
        <mesh filename="package://hmc_v2_hand_description/meshes/agibot_o12_t2_hand/left/left_index_middle.STL"/>
      </geometry>
    </collision>
  </link>
  <joint name="left_index_pip" type="revolute">
    <origin rpy="0 0 0" xyz="-0.0030528 0 0.039907"/>
    <parent link="left_index_proximal"/>
    <child link="left_index_middle"/>
    <axis xyz="0 1 0"/>
    <limit effort="100" lower="0" upper="1.52" velocity="1"/>
  </joint>
  <link name="left_index_distal">
    <inertial>
      <origin rpy="0 0 0" xyz="-0.0072164006985974 -3.10530305492884E-05 0.00510324461394016"/>
      <mass value="0.00258259740989255"/>
      <inertia ixx="1.30227875511426E-07" ixy="1.19682427438751E-10" ixz="4.12783030352628E-08" iyy="1.36472670574212E-07" iyz="-3.14459227086956E-10" izz="1.01017145947709E-07"/>
    </inertial>
    <visual>
      <origin rpy="0 0 0" xyz="0 0 0"/>
      <geometry>
        <mesh filename="package://hmc_v2_hand_description/meshes/agibot_o12_t2_hand/left/left_index_distal.STL"/>
      </geometry>
      <material name="">
        <color rgba="0.792156862745098 0.819607843137255 0.933333333333333 1"/>
      </material>
    </visual>
    <collision>
      <origin rpy="0 0 0" xyz="0 0 0"/>
      <geometry>
        <mesh filename="package://hmc_v2_hand_description/meshes/agibot_o12_t2_hand/left/left_index_distal.STL"/>
      </geometry>
    </collision>
  </link>
  <joint name="left_index_dip" type="revolute">
    <origin rpy="0 0 0" xyz="0.0053069 0 0.026592"/>
    <parent link="left_index_middle"/>
    <child link="left_index_distal"/>
    <axis xyz="0 1 0"/>
    <limit effort="100" lower="0" upper="1.369" velocity="1"/>
    <mimic joint="left_index_pip" multiplier="1" offset="0"/>
  </joint>
  <link name="left_index_Virtual_Point">
    <inertial>
      <origin rpy="0 0 0" xyz="0 -3.46944695195361E-18 0"/>
      <mass value="5.23598775598299E-07"/>
      <inertia ixx="5.23598775598299E-14" ixy="-7.12872725499097E-37" ixz="2.39853897268964E-36" iyy="5.23598775598299E-14" iyz="-1.15642107493289E-30" izz="5.23598775598299E-14"/>
    </inertial>
    <visual>
      <origin rpy="0 0 0" xyz="0 0 0"/>
      <geometry>
        <mesh filename="package://hmc_v2_hand_description/meshes/agibot_o12_t2_hand/left/left_index_Virtual_Point.STL"/>
      </geometry>
      <material name="">
        <color rgba="1 1 1 1"/>
      </material>
    </visual>
    <collision>
      <origin rpy="0 0 0" xyz="0 0 0"/>
      <geometry>
        <mesh filename="package://hmc_v2_hand_description/meshes/agibot_o12_t2_hand/left/left_index_Virtual_Point.STL"/>
      </geometry>
    </collision>
  </link>
  <joint name="left_index_Virtual_Point-none" type="fixed">
    <origin rpy="0 0 0" xyz="-0.0152816222742688 0 0.0240371760926346"/>
    <parent link="left_index_distal"/>
    <child link="left_index_Virtual_Point"/>
    <axis xyz="0 0 0"/>
  </joint>
  <link name="left_middle_metacarpals">
    <inertial>
      <origin rpy="0 0 0" xyz="0.001513443142004 -5.44751168826685E-09 0.00199999158336196"/>
      <mass value="0.00107972492722234"/>
      <inertia ixx="3.54851760205572E-08" ixy="-9.75922605133098E-16" ixz="-2.88674435859045E-09" iyy="2.11264180975021E-08" iyz="-1.69297007027046E-14" izz="3.63609660418816E-08"/>
    </inertial>
    <visual>
      <origin rpy="0 0 0" xyz="0 0 0"/>
      <geometry>
        <mesh filename="package://hmc_v2_hand_description/meshes/agibot_o12_t2_hand/left/left_middle_metacarpals.STL"/>
      </geometry>
      <material name="">
        <color rgba="0.792156862745098 0.819607843137255 0.933333333333333 1"/>
      </material>
    </visual>
    <collision>
      <origin rpy="0 0 0" xyz="0 0 0"/>
      <geometry>
        <mesh filename="package://hmc_v2_hand_description/meshes/agibot_o12_t2_hand/left/left_middle_metacarpals.STL"/>
      </geometry>
    </collision>
  </link>
  <joint name="left_middle_mcp_roll" type="revolute">
    <origin rpy="0 0 0" xyz="-0.0071994 -0.0066607 0.11946"/>
    <parent link="left_hand_base_link"/>
    <child link="left_middle_metacarpals"/>
    <axis xyz="-1 0 0"/>
    <limit effort="100" lower="-0.26" upper="0.26" velocity="1"/>
  </joint>
  <link name="left_middle_proximal">
    <inertial>
      <origin rpy="0 0 0" xyz="-0.00165985154195069 2.4557677021325E-05 0.023622093663244"/>
      <mass value="0.00551224266379775"/>
      <inertia ixx="7.79066394729381E-07" ixy="-4.64147961377332E-12" ixz="3.22743739771861E-08" iyy="7.60603535724366E-07" iyz="-5.92496477681943E-10" izz="2.05879595330157E-07"/>
    </inertial>
    <visual>
      <origin rpy="0 0 0" xyz="0 0 0"/>
      <geometry>
        <mesh filename="package://hmc_v2_hand_description/meshes/agibot_o12_t2_hand/left/left_middle_proximal.STL"/>
      </geometry>
      <material name="">
        <color rgba="0.792156862745098 0.819607843137255 0.933333333333333 1"/>
      </material>
    </visual>
    <collision>
      <origin rpy="0 0 0" xyz="0 0 0"/>
      <geometry>
        <mesh filename="package://hmc_v2_hand_description/meshes/agibot_o12_t2_hand/left/left_middle_proximal.STL"/>
      </geometry>
    </collision>
  </link>
  <joint name="left_middle_mcp_pitch" type="revolute">
    <origin rpy="0 0 0" xyz="0.0073692 0 -9.4996E-05"/>
    <parent link="left_middle_metacarpals"/>
    <child link="left_middle_proximal"/>
    <axis xyz="0 1 0"/>
    <limit effort="100" lower="0" upper="1.35" velocity="1"/>
  </joint>
  <link name="left_middle_middle">
    <inertial>
      <origin rpy="0 0 0" xyz="-0.000230369763452722 2.88460421738763E-05 0.0161975684445981"/>
      <mass value="0.00314204671441198"/>
      <inertia ixx="3.20092568330847E-07" ixy="-3.58688697052903E-11" ixz="1.53073399206161E-08" iyy="2.47015871367737E-07" iyz="2.74053237627201E-11" izz="1.35843044383385E-07"/>
    </inertial>
    <visual>
      <origin rpy="0 0 0" xyz="0 0 0"/>
      <geometry>
        <mesh filename="package://hmc_v2_hand_description/meshes/agibot_o12_t2_hand/left/left_middle_middle.STL"/>
      </geometry>
      <material name="">
        <color rgba="1 1 1 1"/>
      </material>
    </visual>
    <collision>
      <origin rpy="0 0 0" xyz="0 0 0"/>
      <geometry>
        <mesh filename="package://hmc_v2_hand_description/meshes/agibot_o12_t2_hand/left/left_middle_middle.STL"/>
      </geometry>
    </collision>
  </link>
  <joint name="left_middle_pip" type="revolute">
    <origin rpy="0 0 0" xyz="-0.004144 0 0.044828"/>
    <parent link="left_middle_proximal"/>
    <child link="left_middle_middle"/>
    <axis xyz="0 1 0"/>
    <limit effort="100" lower="0" upper="1.814" velocity="1"/>
  </joint>
  <link name="left_middle_distal">
    <inertial>
      <origin rpy="0 0 0" xyz="-0.00724758425654952 -3.1052730819243E-05 0.00505888968194335"/>
      <mass value="0.00258260265037946"/>
      <inertia ixx="1.29720817921799E-07" ixy="1.21614678951735E-10" ixz="4.1454663430862E-08" iyy="1.36473264398442E-07" iyz="-3.13727137759971E-10" izz="1.01524943088101E-07"/>
    </inertial>
    <visual>
      <origin rpy="0 0 0" xyz="0 0 0"/>
      <geometry>
        <mesh filename="package://hmc_v2_hand_description/meshes/agibot_o12_t2_hand/left/left_middle_distal.STL"/>
      </geometry>
      <material name="">
        <color rgba="0.792156862745098 0.819607843137255 0.933333333333333 1"/>
      </material>
    </visual>
    <collision>
      <origin rpy="0 0 0" xyz="0 0 0"/>
      <geometry>
        <mesh filename="package://hmc_v2_hand_description/meshes/agibot_o12_t2_hand/left/left_middle_distal.STL"/>
      </geometry>
    </collision>
  </link>
  <joint name="left_middle_dip" type="revolute">
    <origin rpy="0 0 0" xyz="0.0036295 0 0.031612"/>
    <parent link="left_middle_middle"/>
    <child link="left_middle_distal"/>
    <axis xyz="0 1 0"/>
    <limit effort="100" lower="0" upper="1.256" velocity="1"/>
    <mimic joint="left_middle_pip" multiplier="1" offset="0"/>
  </joint>
  <link name="left_middle_Virtual_Point">
    <inertial>
      <origin rpy="0 0 0" xyz="-6.24500451351651E-17 6.64399091299117E-16 -5.55111512312578E-17"/>
      <mass value="5.23598775598299E-07"/>
      <inertia ixx="5.23598775598299E-14" ixy="-3.60911334838117E-40" ixz="2.76425772861111E-41" iyy="5.23598775598299E-14" iyz="-1.85775742897702E-30" izz="5.23598775598299E-14"/>
    </inertial>
    <visual>
      <origin rpy="0 0 0" xyz="0 0 0"/>
      <geometry>
        <mesh filename="package://hmc_v2_hand_description/meshes/agibot_o12_t2_hand/left/left_middle_Virtual_Point.STL"/>
      </geometry>
      <material name="">
        <color rgba="1 1 1 1"/>
      </material>
    </visual>
    <collision>
      <origin rpy="0 0 0" xyz="0 0 0"/>
      <geometry>
        <mesh filename="package://hmc_v2_hand_description/meshes/agibot_o12_t2_hand/left/left_middle_Virtual_Point.STL"/>
      </geometry>
    </collision>
  </link>
  <joint name="left_middle_Virtual_Point-none" type="fixed">
    <origin rpy="0 0 0" xyz="-0.015429 0 0.023943"/>
    <parent link="left_middle_distal"/>
    <child link="left_middle_Virtual_Point"/>
    <axis xyz="0 0 0"/>
  </joint>
  <link name="left_ring_proximal">
    <inertial>
      <origin rpy="0 0 0" xyz="-0.00161802177937932 -2.08220506989678E-05 0.0212342176491597"/>
      <mass value="0.00477953283061717"/>
      <inertia ixx="5.43923248642547E-07" ixy="-8.48911319307107E-11" ixz="2.46894777187068E-08" iyy="5.41640125900586E-07" iyz="-2.52181318799242E-10" izz="1.76501745957818E-07"/>
    </inertial>
    <visual>
      <origin rpy="0 0 0" xyz="0 0 0"/>
      <geometry>
        <mesh filename="package://hmc_v2_hand_description/meshes/agibot_o12_t2_hand/left/left_ring_proximal.STL"/>
      </geometry>
      <material name="">
        <color rgba="1 1 1 1"/>
      </material>
    </visual>
    <collision>
      <origin rpy="0 0 0" xyz="0 0 0"/>
      <geometry>
        <mesh filename="package://hmc_v2_hand_description/meshes/agibot_o12_t2_hand/left/left_ring_proximal.STL"/>
      </geometry>
    </collision>
  </link>
  <joint name="left_ring_mcp_pitch" type="revolute">
    <origin rpy="0 0 0" xyz="0.0001598 0.013573 0.11972"/>
    <parent link="left_hand_base_link"/>
    <child link="left_ring_proximal"/>
    <axis xyz="0 1 0"/>
    <limit effort="100" lower="0" upper="1.55" velocity="1"/>
  </joint>
  <link name="left_ring_middle">
    <inertial>
      <origin rpy="0 0 0" xyz="0.000940447905390568 -1.66667501774048E-05 0.013421630768871"/>
      <mass value="0.00270775337558511"/>
      <inertia ixx="2.25767885628129E-07" ixy="4.61314413767225E-12" ixz="2.32214874086729E-09" iyy="1.61875512518121E-07" iyz="-9.05905844323353E-12" izz="1.17700101184182E-07"/>
    </inertial>
    <visual>
      <origin rpy="0 0 0" xyz="0 0 0"/>
      <geometry>
        <mesh filename="package://hmc_v2_hand_description/meshes/agibot_o12_t2_hand/left/left_ring_middle.STL"/>
      </geometry>
      <material name="">
        <color rgba="0 0 0 1"/>
      </material>
    </visual>
    <collision>
      <origin rpy="0 0 0" xyz="0 0 0"/>
      <geometry>
        <mesh filename="package://hmc_v2_hand_description/meshes/agibot_o12_t2_hand/left/left_ring_middle.STL"/>
      </geometry>
    </collision>
  </link>
  <joint name="left_ring_pip" type="revolute">
    <origin rpy="0 0 0" xyz="-0.0039295 0 0.03983"/>
    <parent link="left_ring_proximal"/>
    <child link="left_ring_middle"/>
    <axis xyz="0 1 0"/>
    <limit effort="100" lower="0" upper="1.439" velocity="1"/>
    <mimic joint="left_ring_mcp_pitch" multiplier="1" offset="0"/>
  </joint>
  <link name="left_ring_distal">
    <inertial>
      <origin rpy="0 0 0" xyz="-0.00679186135685795 -3.10514206139905E-05 0.0056558951654784"/>
      <mass value="0.00258259191907092"/>
      <inertia ixx="1.365300193362E-07" ixy="9.44469493284984E-11" ixz="3.84709877030533E-08" iyy="1.36471656656412E-07" iyz="-3.22660701215699E-10" izz="9.47138987606997E-08"/>
    </inertial>
    <visual>
      <origin rpy="0 0 0" xyz="0 0 0"/>
      <geometry>
        <mesh filename="package://hmc_v2_hand_description/meshes/agibot_o12_t2_hand/left/left_ring_distal.STL"/>
      </geometry>
      <material name="">
        <color rgba="0.792156862745098 0.819607843137255 0.933333333333333 1"/>
      </material>
    </visual>
    <collision>
      <origin rpy="0 0 0" xyz="0 0 0"/>
      <geometry>
        <mesh filename="package://hmc_v2_hand_description/meshes/agibot_o12_t2_hand/left/left_ring_distal.STL"/>
      </geometry>
    </collision>
  </link>
  <joint name="left_ring_dip" type="revolute">
    <origin rpy="0 0 0" xyz="0.0060129 0 0.026442"/>
    <parent link="left_ring_middle"/>
    <child link="left_ring_distal"/>
    <axis xyz="0 1 0"/>
    <limit effort="100" lower="0" upper="1.3257" velocity="1"/>
    <mimic joint="left_ring_mcp_pitch" multiplier="1" offset="0"/>
  </joint>
  <link name="left_ring_Virtual_Point">
    <inertial>
      <origin rpy="0 0 0" xyz="5.55111512312578E-16 1.73472347597681E-18 5.55111512312578E-17"/>
      <mass value="5.23598775598299E-07"/>
      <inertia ixx="5.23598775598299E-14" ixy="-9.51609985897613E-36" ixz="-2.06849307477768E-35" iyy="5.23598775598299E-14" iyz="1.85037170827187E-30" izz="5.23598775598299E-14"/>
    </inertial>
    <visual>
      <origin rpy="0 0 0" xyz="0 0 0"/>
      <geometry>
        <mesh filename="package://hmc_v2_hand_description/meshes/agibot_o12_t2_hand/left/left_ring_Virtual_Point.STL"/>
      </geometry>
      <material name="">
        <color rgba="1 1 1 1"/>
      </material>
    </visual>
    <collision>
      <origin rpy="0 0 0" xyz="0 0 0"/>
      <geometry>
        <mesh filename="package://hmc_v2_hand_description/meshes/agibot_o12_t2_hand/left/left_ring_Virtual_Point.STL"/>
      </geometry>
    </collision>
  </link>
  <joint name="left_ring_Virtual_Point-none" type="fixed">
    <origin rpy="0 0 0" xyz="-0.01334 0 0.025166"/>
    <parent link="left_ring_distal"/>
    <child link="left_ring_Virtual_Point"/>
    <axis xyz="0 0 0"/>
  </joint>
  <link name="left_pinky_proximal">
    <inertial>
      <origin rpy="0 0 0" xyz="-0.0016180221168521 -2.08215074695289E-05 0.0212342179851402"/>
      <mass value="0.00477953323340541"/>
      <inertia ixx="5.43923274544673E-07" ixy="-8.48863445397533E-11" ixz="2.46894910332365E-08" iyy="5.41640168354855E-07" iyz="-2.52187730642466E-10" izz="1.7650175778066E-07"/>
    </inertial>
    <visual>
      <origin rpy="0 0 0" xyz="0 0 0"/>
      <geometry>
        <mesh filename="package://hmc_v2_hand_description/meshes/agibot_o12_t2_hand/left/left_pinky_proximal.STL"/>
      </geometry>
      <material name="">
        <color rgba="1 1 1 1"/>
      </material>
    </visual>
    <collision>
      <origin rpy="0 0 0" xyz="0 0 0"/>
      <geometry>
        <mesh filename="package://hmc_v2_hand_description/meshes/agibot_o12_t2_hand/left/left_pinky_proximal.STL"/>
      </geometry>
    </collision>
  </link>
  <joint name="left_pinky_mcp_pitch" type="revolute">
    <origin rpy="0 0 0" xyz="0.0001598 0.03363 0.11272"/>
    <parent link="left_hand_base_link"/>
    <child link="left_pinky_proximal"/>
    <axis xyz="0 1 0"/>
    <limit effort="100" lower="0" upper="1.535" velocity="1"/>
  </joint>
  <link name="left_pinky_middle">
    <inertial>
      <origin rpy="0 0 0" xyz="0.000940340858988643 -1.6666852345866E-05 0.0134216382102795"/>
      <mass value="0.00270775341133159"/>
      <inertia ixx="2.25767852098342E-07" ixy="4.61323165677339E-12" ixz="2.32301105485376E-09" iyy="1.61875515034515E-07" iyz="-9.06111359635607E-12" izz="1.1770013929689E-07"/>
    </inertial>
    <visual>
      <origin rpy="0 0 0" xyz="0 0 0"/>
      <geometry>
        <mesh filename="package://hmc_v2_hand_description/meshes/agibot_o12_t2_hand/left/left_pinky_middle.STL"/>
      </geometry>
      <material name="">
        <color rgba="0 0 0 1"/>
      </material>
    </visual>
    <collision>
      <origin rpy="0 0 0" xyz="0 0 0"/>
      <geometry>
        <mesh filename="package://hmc_v2_hand_description/meshes/agibot_o12_t2_hand/left/left_pinky_middle.STL"/>
      </geometry>
    </collision>
  </link>
  <joint name="left_pinky_pip" type="revolute">
    <origin rpy="0 0 0" xyz="-0.0039295 0 0.03983"/>
    <parent link="left_pinky_proximal"/>
    <child link="left_pinky_middle"/>
    <axis xyz="0 1 0"/>
    <limit effort="100" lower="0" upper="1.413" velocity="1"/>
    <mimic joint="left_pinky_mcp_pitch" multiplier="1" offset="0"/>
  </joint>
  <link name="left_pinky_distal">
    <inertial>
      <origin rpy="0 0 0" xyz="-0.00679190138001771 -3.10516578322304E-05 0.00565584691673574"/>
      <mass value="0.0025825918864764"/>
      <inertia ixx="1.36529472111252E-07" ixy="9.44467318754025E-11" ixz="3.84712826230557E-08" iyy="1.36471652160676E-07" iyz="-3.2265582569779E-10" izz="9.47144453976082E-08"/>
    </inertial>
    <visual>
      <origin rpy="0 0 0" xyz="0 0 0"/>
      <geometry>
        <mesh filename="package://hmc_v2_hand_description/meshes/agibot_o12_t2_hand/left/left_pinky_distal.STL"/>
      </geometry>
      <material name="">
        <color rgba="0.792156862745098 0.819607843137255 0.933333333333333 1"/>
      </material>
    </visual>
    <collision>
      <origin rpy="0 0 0" xyz="0 0 0"/>
      <geometry>
        <mesh filename="package://hmc_v2_hand_description/meshes/agibot_o12_t2_hand/left/left_pinky_distal.STL"/>
      </geometry>
    </collision>
  </link>
  <joint name="left_pinky_dip" type="revolute">
    <origin rpy="0 0 0" xyz="0.0060127 0 0.026442"/>
    <parent link="left_pinky_middle"/>
    <child link="left_pinky_distal"/>
    <axis xyz="0 1 0"/>
    <limit effort="100" lower="0" upper="1.325" velocity="1"/>
    <mimic joint="left_pinky_mcp_pitch" multiplier="1" offset="0"/>
  </joint>
  <link name="left_pinky_Virtual_Point">
    <inertial>
      <origin rpy="0 0 0" xyz="-1.73472347597681E-18 6.93889390390723E-18 2.77555756156289E-17"/>
      <mass value="5.23598775598299E-07"/>
      <inertia ixx="5.23598775598299E-14" ixy="-1.60381510490316E-37" ixz="-1.49418255470987E-37" iyy="5.23598775598299E-14" iyz="-2.59800115709611E-31" izz="5.23598775598299E-14"/>
    </inertial>
    <visual>
      <origin rpy="0 0 0" xyz="0 0 0"/>
      <geometry>
        <mesh filename="package://hmc_v2_hand_description/meshes/agibot_o12_t2_hand/left/left_pinky_Virtual_Point.STL"/>
      </geometry>
      <material name="">
        <color rgba="1 1 1 1"/>
      </material>
    </visual>
    <collision>
      <origin rpy="0 0 0" xyz="0 0 0"/>
      <geometry>
        <mesh filename="package://hmc_v2_hand_description/meshes/agibot_o12_t2_hand/left/left_pinky_Virtual_Point.STL"/>
      </geometry>
    </collision>
  </link>
  <joint name="left_pinky_Virtual_Point-none" type="fixed">
    <origin rpy="0 0 0" xyz="-0.01334 0 0.025166"/>
    <parent link="left_pinky_distal"/>
    <child link="left_pinky_Virtual_Point"/>
    <axis xyz="0 0 0"/>
  </joint>
  <link name="right_hand_base_link">
    <inertial>
      <origin rpy="0 0 0" xyz="-0.00161159551039664 -5.35320731301112E-05 0.0560978412942799"/>
      <mass value="0.114811257443678"/>
      <inertia ixx="0.000157668014286336" ixy="1.23279816628469E-07" ixz="3.41927928857369E-06" iyy="8.5350303174068E-05" iyz="-3.29579297268573E-06" izz="8.65455243809675E-05"/>
    </inertial>
    <visual>
      <origin rpy="0 0 0" xyz="0 0 0"/>
      <geometry>
        <mesh filename="package://hmc_v2_hand_description/meshes/agibot_o12_t2_hand/right/right_hand_base_link.STL"/>
      </geometry>
      <material name="">
        <color rgba="0.792156862745098 0.819607843137255 0.933333333333333 1"/>
      </material>
    </visual>
    <collision>
      <origin rpy="0 0 0" xyz="0 0 0"/>
      <geometry>
        <mesh filename="package://hmc_v2_hand_description/meshes/agibot_o12_t2_hand/right/right_hand_base_link.STL"/>
      </geometry>
    </collision>
  </link>
  <link name="right_thumb_metacarpals_base1">
    <inertial>
      <origin rpy="0 0 0" xyz="0.0128313930736693 -0.000678732032779711 -6.35818794832849E-05"/>
      <mass value="0.00393646374828629"/>
      <inertia ixx="5.66342021103653E-07" ixy="2.99828694401975E-08" ixz="-8.5308152999029E-10" iyy="2.92953553344946E-07" iyz="1.9125859446091E-08" izz="6.19998879375208E-07"/>
    </inertial>
    <visual>
      <origin rpy="0 0 0" xyz="0 0 0"/>
      <geometry>
        <mesh filename="package://hmc_v2_hand_description/meshes/agibot_o12_t2_hand/right/right_thumb_metacarpals_base1.STL"/>
      </geometry>
      <material name="">
        <color rgba="1 1 1 1"/>
      </material>
    </visual>
    <collision>
      <origin rpy="0 0 0" xyz="0 0 0"/>
      <geometry>
        <mesh filename="package://hmc_v2_hand_description/meshes/agibot_o12_t2_hand/right/right_thumb_metacarpals_base1.STL"/>
      </geometry>
    </collision>
  </link>
  <joint name="right_thumb_cmc_roll" type="revolute">
    <origin rpy="0 0 0" xyz="-0.0075211 0.022278 0.04025"/>
    <parent link="right_hand_base_link"/>
    <child link="right_thumb_metacarpals_base1"/>
    <axis xyz="1 0 0"/>
    <limit effort="100" lower="-0.2930" upper="0.6489" velocity="1"/>
  </joint>
  <link name="right_thumb_metacarpals_base2">
    <inertial>
      <origin rpy="0 0 0" xyz="0.00581591430824001 0.00635157624424623 0.0030181797779424"/>
      <mass value="0.00171679583795965"/>
      <inertia ixx="1.18471956476211E-07" ixy="-4.21491727713665E-08" ixz="-1.05144206441241E-08" iyy="1.14929858642022E-07" iyz="-1.74178188232578E-08" izz="9.67476477234771E-08"/>
    </inertial>
    <visual>
      <origin rpy="0 0 0" xyz="0 0 0"/>
      <geometry>
        <mesh filename="package://hmc_v2_hand_description/meshes/agibot_o12_t2_hand/right/right_thumb_metacarpals_base2.STL"/>
      </geometry>
      <material name="">
        <color rgba="1 1 1 1"/>
      </material>
    </visual>
    <collision>
      <origin rpy="0 0 0" xyz="0 0 0"/>
      <geometry>
        <mesh filename="package://hmc_v2_hand_description/meshes/agibot_o12_t2_hand/right/right_thumb_metacarpals_base2.STL"/>
      </geometry>
    </collision>
  </link>
  <joint name="right_thumb_cmc_yaw" type="revolute">
    <origin rpy="0 0 0" xyz="0.0350706488516897 0.00330139200274943 0"/>
    <parent link="right_thumb_metacarpals_base1"/>
    <child link="right_thumb_metacarpals_base2"/>
    <axis xyz="0 0 -1"/>
    <limit effort="100" lower="0" upper="1.3868" velocity="1"/>
  </joint>
  <link name="right_thumb_metacarpals">
    <inertial>
      <origin rpy="0 0 0" xyz="0.00385872987613253 0.000181218415040837 0.0262735842223975"/>
      <mass value="0.0170904824194818"/>
      <inertia ixx="6.63118248451921E-06" ixy="-8.89148786987225E-09" ixz="-3.40233793822337E-07" iyy="8.03870891218123E-06" iyz="1.37099535870765E-08" izz="1.83070429843817E-06"/>
    </inertial>
    <visual>
      <origin rpy="0 0 0" xyz="0 0 0"/>
      <geometry>
        <mesh filename="package://hmc_v2_hand_description/meshes/agibot_o12_t2_hand/right/right_thumb_metacarpals.STL"/>
      </geometry>
      <material name="">
        <color rgba="1 1 1 1"/>
      </material>
    </visual>
    <collision>
      <origin rpy="0 0 0" xyz="0 0 0"/>
      <geometry>
        <mesh filename="package://hmc_v2_hand_description/meshes/agibot_o12_t2_hand/right/right_thumb_metacarpals.STL"/>
      </geometry>
    </collision>
  </link>
  <joint name="right_thumb_cmc_pitch" type="revolute">
    <origin rpy="0 -0.925290064543775 -2.35079106633742" xyz="0.0161297170352622 0.0163048601861332 0.00686106204760886"/>
    <parent link="right_thumb_metacarpals_base2"/>
    <child link="right_thumb_metacarpals"/>
    <axis xyz="0 1 0"/>
    <limit effort="100" lower="0" upper="0.8268" velocity="1"/>
  </joint>
  <link name="right_thumb_proximal">
    <inertial>
      <origin rpy="0 0 0" xyz="-0.00245377652568594 0.00186599902568424 0.0134436674550769"/>
      <mass value="0.00522967724458737"/>
      <inertia ixx="4.48792018896274E-07" ixy="-9.70789943838585E-10" ixz="-7.98090430081374E-08" iyy="6.21158736091837E-07" iyz="-3.64664957781825E-09" izz="2.2512440353929E-07"/>
    </inertial>
    <visual>
      <origin rpy="0 0 0" xyz="0 0 0"/>
      <geometry>
        <mesh filename="package://hmc_v2_hand_description/meshes/agibot_o12_t2_hand/right/right_thumb_proximal.STL"/>
      </geometry>
      <material name="">
        <color rgba="0.792156862745098 0.819607843137255 0.933333333333333 1"/>
      </material>
    </visual>
    <collision>
      <origin rpy="0 0 0" xyz="0 0 0"/>
      <geometry>
        <mesh filename="package://hmc_v2_hand_description/meshes/agibot_o12_t2_hand/right/right_thumb_proximal.STL"/>
      </geometry>
    </collision>
  </link>
  <joint name="right_thumb_mcp" type="revolute">
    <origin rpy="0 0 0" xyz="0.00816453404663862 -0.00144999989303646 0.0556339310817644"/>
    <parent link="right_thumb_metacarpals"/>
    <child link="right_thumb_proximal"/>
    <axis xyz="0 1 0"/>
    <limit effort="100" lower="0" upper="1.2908" velocity="1"/>
  </joint>
  <link name="right_thumb_distal">
    <inertial>
      <origin rpy="0 0 0" xyz="0.000428123853169746 2.07014406468898E-05 0.00928509405558531"/>
      <mass value="0.00521800975168049"/>
      <inertia ixx="3.59710358459503E-07" ixy="-7.03000203960055E-11" ixz="7.69465079824501E-08" iyy="3.45473494359169E-07" iyz="3.06962101858862E-10" izz="2.64028535580618E-07"/>
    </inertial>
    <visual>
      <origin rpy="0 0 0" xyz="0 0 0"/>
      <geometry>
        <mesh filename="package://hmc_v2_hand_description/meshes/agibot_o12_t2_hand/right/right_thumb_distal.STL"/>
      </geometry>
      <material name="">
        <color rgba="0.796078431372549 0.823529411764706 0.937254901960784 1"/>
      </material>
    </visual>
    <collision>
      <origin rpy="0 0 0" xyz="0 0 0"/>
      <geometry>
        <mesh filename="package://hmc_v2_hand_description/meshes/agibot_o12_t2_hand/right/right_thumb_distal.STL"/>
      </geometry>
    </collision>
  </link>
  <joint name="right_thumb_ip" type="revolute">
    <origin rpy="0 0 0" xyz="-0.00154750718363847 0.00149999983118392 0.0345280593371561"/>
    <parent link="right_thumb_proximal"/>
    <child link="right_thumb_distal"/>
    <axis xyz="0 1 0"/>
    <limit effort="100" lower="0" upper="1.3781" velocity="1"/>
    <mimic joint="right_thumb_mcp" multiplier="1" offset="0"/>
  </joint>
  <link name="right_thumb_Virtual_Point">
    <inertial>
      <origin rpy="0 0 0" xyz="0.000233035989326169 5.00064540250775E-05 4.67970036186205E-05"/>
      <mass value="5.23598775598299E-07"/>
      <inertia ixx="5.23598775598299E-14" ixy="-6.44905165041911E-31" ixz="3.15544362088405E-30" iyy="5.23598775598299E-14" iyz="-2.42380465218649E-30" izz="5.23598775598299E-14"/>
    </inertial>
    <visual>
      <origin rpy="0 0 0" xyz="0 0 0"/>
      <geometry>
        <mesh filename="package://hmc_v2_hand_description/meshes/agibot_o12_t2_hand/right/right_thumb_Virtual_Point.STL"/>
      </geometry>
      <material name="">
        <color rgba="1 1 1 1"/>
      </material>
    </visual>
    <collision>
      <origin rpy="0 0 0" xyz="0 0 0"/>
      <geometry>
        <mesh filename="package://hmc_v2_hand_description/meshes/agibot_o12_t2_hand/right/right_thumb_Virtual_Point.STL"/>
      </geometry>
    </collision>
  </link>
  <joint name="right_thumb_Virtual_Point-none" type="fixed">
    <origin rpy="0 0 0" xyz="-0.00661702686299999 -4.99999381474688E-05 0.0315676558844293"/>
    <parent link="right_thumb_distal"/>
    <child link="right_thumb_Virtual_Point"/>
    <axis xyz="0 0 0"/>
  </joint>
  <link name="right_index_metacarpals">
    <inertial>
      <origin rpy="0 0 0" xyz="0.00148754096391645 -5.49503463911916E-09 0.0020193309982513"/>
      <mass value="0.00107972483821526"/>
      <inertia ixx="3.55597226363628E-08" ixy="-9.48374824931894E-16" ixz="-2.89707226372672E-09" iyy="2.11264180987165E-08" iyz="-1.72178782545344E-14" izz="3.62864110573929E-08"/>
    </inertial>
    <visual>
      <origin rpy="0 0 0" xyz="0 0 0"/>
      <geometry>
        <mesh filename="package://hmc_v2_hand_description/meshes/agibot_o12_t2_hand/right/right_index_metacarpals.STL"/>
      </geometry>
      <material name="">
        <color rgba="0.792156862745098 0.819607843137255 0.933333333333333 1"/>
      </material>
    </visual>
    <collision>
      <origin rpy="0 0 0" xyz="0 0 0"/>
      <geometry>
        <mesh filename="package://hmc_v2_hand_description/meshes/agibot_o12_t2_hand/right/right_index_metacarpals.STL"/>
      </geometry>
    </collision>
  </link>
  <joint name="right_index_mcp_roll" type="revolute">
    <origin rpy="0 0 0" xyz="-0.00719999999308767 0.030778354272632 0.119355702147758"/>
    <parent link="right_hand_base_link"/>
    <child link="right_index_metacarpals"/>
    <axis xyz="1 0 0"/>
    <limit effort="100" lower="-0.2616" upper="0.2616" velocity="1"/>
  </joint>
  <link name="right_index_proximal">
    <inertial>
      <origin rpy="0 0 0" xyz="-0.0011507020809311 -2.08334184405266E-05 0.0212647300382613"/>
      <mass value="0.0047795679529425"/>
      <inertia ixx="5.44832577804325E-07" ixy="-9.05372082062046E-11" ixz="1.65895588180974E-08" iyy="5.41640689587984E-07" iyz="-2.49910298343712E-10" izz="1.75594690124638E-07"/>
    </inertial>
    <visual>
      <origin rpy="0 0 0" xyz="0 0 0"/>
      <geometry>
        <mesh filename="package://hmc_v2_hand_description/meshes/agibot_o12_t2_hand/right/right_index_proximal.STL"/>
      </geometry>
      <material name="">
        <color rgba="1 1 1 1"/>
      </material>
    </visual>
    <collision>
      <origin rpy="0 0 0" xyz="0 0 0"/>
      <geometry>
        <mesh filename="package://hmc_v2_hand_description/meshes/agibot_o12_t2_hand/right/right_index_proximal.STL"/>
      </geometry>
    </collision>
  </link>
  <joint name="right_index_mcp_pitch" type="revolute">
    <origin rpy="0 0 0" xyz="0.00736980261911774 0 0"/>
    <parent link="right_index_metacarpals"/>
    <child link="right_index_proximal"/>
    <axis xyz="0 1 0"/>
    <limit effort="100" lower="0" upper="1.3519" velocity="1"/>
  </joint>
  <link name="right_index_middle">
    <inertial>
      <origin rpy="0 0 0" xyz="0.000582798950647259 -1.66623930000845E-05 0.0134419047168478"/>
      <mass value="0.00270775195657711"/>
      <inertia ixx="2.25567812011315E-07" ixy="4.76559542406049E-12" ixz="5.19477924230877E-09" iyy="1.61875481956388E-07" iyz="-8.958112771538E-12" izz="1.1790038033522E-07"/>
    </inertial>
    <visual>
      <origin rpy="0 0 0" xyz="0 0 0"/>
      <geometry>
        <mesh filename="package://hmc_v2_hand_description/meshes/agibot_o12_t2_hand/right/right_index_middle.STL"/>
      </geometry>
      <material name="">
        <color rgba="0 0 0 1"/>
      </material>
    </visual>
    <collision>
      <origin rpy="0 0 0" xyz="0 0 0"/>
      <geometry>
        <mesh filename="package://hmc_v2_hand_description/meshes/agibot_o12_t2_hand/right/right_index_middle.STL"/>
      </geometry>
    </collision>
  </link>
  <joint name="right_index_pip" type="revolute">
    <origin rpy="0 0 0" xyz="-0.00305282449335901 0 0.0399071116817979"/>
    <parent link="right_index_proximal"/>
    <child link="right_index_middle"/>
    <axis xyz="0 1 0"/>
    <limit effort="100" lower="0" upper="1.52" velocity="1"/>
  </joint>
  <link name="right_index_distal">
    <inertial>
      <origin rpy="0 0 0" xyz="-0.00721640324456499 -3.10526118675776E-05 0.00510323974876059"/>
      <mass value="0.00258259704107596"/>
      <inertia ixx="1.30227806624487E-07" ixy="1.19687371568575E-10" ixz="4.12783102703161E-08" iyy="1.36472647538679E-07" iyz="-3.14466372715903E-10" izz="1.01017185875891E-07"/>
    </inertial>
    <visual>
      <origin rpy="0 0 0" xyz="0 0 0"/>
      <geometry>
        <mesh filename="package://hmc_v2_hand_description/meshes/agibot_o12_t2_hand/right/right_index_distal.STL"/>
      </geometry>
      <material name="">
        <color rgba="0.792156862745098 0.819607843137255 0.933333333333333 1"/>
      </material>
    </visual>
    <collision>
      <origin rpy="0 0 0" xyz="0 0 0"/>
      <geometry>
        <mesh filename="package://hmc_v2_hand_description/meshes/agibot_o12_t2_hand/right/right_index_distal.STL"/>
      </geometry>
    </collision>
  </link>
  <joint name="right_index_dip" type="revolute">
    <origin rpy="0 0 0" xyz="0.00530686089658646 0 0.0265922869892696"/>
    <parent link="right_index_middle"/>
    <child link="right_index_distal"/>
    <axis xyz="0 1 0"/>
    <limit effort="100" lower="0" upper="1.369" velocity="1"/>
    <mimic joint="right_index_pip" multiplier="1" offset="0"/>
  </joint>
  <link name="right_index_Virtual_Point">
    <inertial>
      <origin rpy="0 0 0" xyz="2.59494682686157E-12 1.08447278934776E-12 -2.77555756156289E-17"/>
      <mass value="5.23598775598299E-07"/>
      <inertia ixx="5.23598775598299E-14" ixy="1.25598008635388E-40" ixz="9.28286640364503E-41" iyy="5.23598775598299E-14" iyz="1.09865815136825E-30" izz="5.23598775598299E-14"/>
    </inertial>
    <visual>
      <origin rpy="0 0 0" xyz="0 0 0"/>
      <geometry>
        <mesh filename="package://hmc_v2_hand_description/meshes/agibot_o12_t2_hand/right/right_index_Virtual_Point.STL"/>
      </geometry>
      <material name="">
        <color rgba="1 1 1 1"/>
      </material>
    </visual>
    <collision>
      <origin rpy="0 0 0" xyz="0 0 0"/>
      <geometry>
        <mesh filename="package://hmc_v2_hand_description/meshes/agibot_o12_t2_hand/right/right_index_Virtual_Point.STL"/>
      </geometry>
    </collision>
  </link>
  <joint name="right_index_Virtual_Point-none" type="fixed">
    <origin rpy="0 0 0" xyz="-0.0152816370939128 0 0.0240371666710466"/>
    <parent link="right_index_distal"/>
    <child link="right_index_Virtual_Point"/>
    <axis xyz="0 0 0"/>
  </joint>
  <link name="right_middle_metacarpals">
    <inertial>
      <origin rpy="0 0 0" xyz="0.00148754096057072 3.28886513297454E-06 0.00201932832117667"/>
      <mass value="0.00107972484789827"/>
      <inertia ixx="3.55597227804492E-08" ixy="-4.72744773072463E-12" ixz="-2.89706838785042E-09" iyy="2.11264584194102E-08" iyz="2.47147540874508E-11" izz="3.62863711473445E-08"/>
    </inertial>
    <visual>
      <origin rpy="0 0 0" xyz="0 0 0"/>
      <geometry>
        <mesh filename="package://hmc_v2_hand_description/meshes/agibot_o12_t2_hand/right/right_middle_metacarpals.STL"/>
      </geometry>
      <material name="">
        <color rgba="0.792156862745098 0.819607843137255 0.933333333333333 1"/>
      </material>
    </visual>
    <collision>
      <origin rpy="0 0 0" xyz="0 0 0"/>
      <geometry>
        <mesh filename="package://hmc_v2_hand_description/meshes/agibot_o12_t2_hand/right/right_middle_metacarpals.STL"/>
      </geometry>
    </collision>
  </link>
  <joint name="right_middle_mcp_roll" type="revolute">
    <origin rpy="0 0 0" xyz="-0.00720002856790489 0.00666067883725946 0.119355672566023"/>
    <parent link="right_hand_base_link"/>
    <child link="right_middle_metacarpals"/>
    <axis xyz="1 0 0"/>
    <limit effort="100" lower="-0.26" upper="0.26" velocity="1"/>
  </joint>
  <link name="right_middle_proximal">
    <inertial>
      <origin rpy="0 0 0" xyz="-0.00165985032192234 6.30950482594017E-05 0.0236220231228174"/>
      <mass value="0.0055122415444485"/>
      <inertia ixx="7.79066281858944E-07" ixy="4.80058757068528E-11" ixz="3.22743653411331E-08" iyy="7.60600012773068E-07" iyz="-1.49750195774983E-09" izz="2.05882994190045E-07"/>
    </inertial>
    <visual>
      <origin rpy="0 0 0" xyz="0 0 0"/>
      <geometry>
        <mesh filename="package://hmc_v2_hand_description/meshes/agibot_o12_t2_hand/right/right_middle_proximal.STL"/>
      </geometry>
      <material name="">
        <color rgba="0.792156862745098 0.819607843137255 0.933333333333333 1"/>
      </material>
    </visual>
    <collision>
      <origin rpy="0 0 0" xyz="0 0 0"/>
      <geometry>
        <mesh filename="package://hmc_v2_hand_description/meshes/agibot_o12_t2_hand/right/right_middle_proximal.STL"/>
      </geometry>
    </collision>
  </link>
  <joint name="right_middle_mcp_pitch" type="revolute">
    <origin rpy="0 0 0" xyz="0.00736980261904721 0 0"/>
    <parent link="right_middle_metacarpals"/>
    <child link="right_middle_proximal"/>
    <axis xyz="0 0.999998669223613 -0.00163142606439766"/>
    <limit effort="100" lower="0" upper="1.35" velocity="1"/>
  </joint>
  <link name="right_middle_middle">
    <inertial>
      <origin rpy="0 0 0" xyz="-0.000230368247225323 5.52667321999743E-05 0.01619749717231"/>
      <mass value="0.00314204808883818"/>
      <inertia ixx="3.20092678111392E-07" ixy="-1.08641100687577E-11" ixz="1.53074298945201E-08" iyy="2.47015765909473E-07" iyz="-1.53970978537133E-10" izz="1.35843361683385E-07"/>
    </inertial>
    <visual>
      <origin rpy="0 0 0" xyz="0 0 0"/>
      <geometry>
        <mesh filename="package://hmc_v2_hand_description/meshes/agibot_o12_t2_hand/right/right_middle_middle.STL"/>
      </geometry>
      <material name="">
        <color rgba="1 1 1 1"/>
      </material>
    </visual>
    <collision>
      <origin rpy="0 0 0" xyz="0 0 0"/>
      <geometry>
        <mesh filename="package://hmc_v2_hand_description/meshes/agibot_o12_t2_hand/right/right_middle_middle.STL"/>
      </geometry>
    </collision>
  </link>
  <joint name="right_middle_pip" type="revolute">
    <origin rpy="0 0 0" xyz="-0.004144 7.3133E-05 0.044828"/>
    <parent link="right_middle_proximal"/>
    <child link="right_middle_middle"/>
    <axis xyz="0 1 -0.0016314"/>
    <limit effort="100" lower="0" upper="1.814" velocity="1"/>
  </joint>
  <link name="right_middle_distal">
    <inertial>
      <origin rpy="0 0 0" xyz="-0.00724758468028898 -2.27990144281735E-05 0.00505893372906674"/>
      <mass value="0.00258260294313138"/>
      <inertia ixx="1.29720848656837E-07" ixy="1.8924389897908E-10" ixz="4.14544297269987E-08" iyy="1.36472188916914E-07" iyz="-3.70737066885826E-10" izz="1.01526072268206E-07"/>
    </inertial>
    <visual>
      <origin rpy="0 0 0" xyz="0 0 0"/>
      <geometry>
        <mesh filename="package://hmc_v2_hand_description/meshes/agibot_o12_t2_hand/right/right_middle_distal.STL"/>
      </geometry>
      <material name="">
        <color rgba="0.792156862745098 0.819607843137255 0.933333333333333 1"/>
      </material>
    </visual>
    <collision>
      <origin rpy="0 0 0" xyz="0 0 0"/>
      <geometry>
        <mesh filename="package://hmc_v2_hand_description/meshes/agibot_o12_t2_hand/right/right_middle_distal.STL"/>
      </geometry>
    </collision>
  </link>
  <joint name="right_middle_dip" type="revolute">
    <origin rpy="0 0 0" xyz="0.00362953932909984 5.15731342090597E-05 0.031612259069028"/>
    <parent link="right_middle_middle"/>
    <child link="right_middle_distal"/>
    <axis xyz="0 0.99999866922354 -0.0016314261089444"/>
    <limit effort="100" lower="0" upper="1.256" velocity="1"/>
    <mimic joint="right_middle_pip" multiplier="1" offset="0"/>
  </joint>
  <link name="right_middle_Virtual_Point">
    <inertial>
      <origin rpy="0 0 0" xyz="4.81580053612873E-13 1.33037331151442E-12 -6.74460487459783E-15"/>
      <mass value="5.23598775598299E-07"/>
      <inertia ixx="5.23598775598299E-14" ixy="-4.90325426925644E-42" ixz="1.17662710661929E-40" iyy="5.23598775598299E-14" iyz="1.29845462914076E-30" izz="5.23598775598299E-14"/>
    </inertial>
    <visual>
      <origin rpy="0 0 0" xyz="0 0 0"/>
      <geometry>
        <mesh filename="package://hmc_v2_hand_description/meshes/agibot_o12_t2_hand/right/right_middle_Virtual_Point.STL"/>
      </geometry>
      <material name="">
        <color rgba="1 1 1 1"/>
      </material>
    </visual>
    <collision>
      <origin rpy="0 0 0" xyz="0 0 0"/>
      <geometry>
        <mesh filename="package://hmc_v2_hand_description/meshes/agibot_o12_t2_hand/right/right_middle_Virtual_Point.STL"/>
      </geometry>
    </collision>
  </link>
  <joint name="right_middle_Virtual_Point-none" type="fixed">
    <origin rpy="0 0 0" xyz="-0.0154287963750709 3.90611932357243E-05 0.0239429432292471"/>
    <parent link="right_middle_distal"/>
    <child link="right_middle_Virtual_Point"/>
    <axis xyz="0 0 0"/>
  </joint>
  <link name="right_ring_proximal">
    <inertial>
      <origin rpy="0 0 0" xyz="-0.00161802170047008 -2.08220096852268E-05 0.0212342177709951"/>
      <mass value="0.0047795328266326"/>
      <inertia ixx="5.43923252152409E-07" ixy="-8.48896522637981E-11" ixz="2.4689478865027E-08" iyy="5.41640127982143E-07" iyz="-2.5218290048469E-10" izz="1.76501748993068E-07"/>
    </inertial>
    <visual>
      <origin rpy="0 0 0" xyz="0 0 0"/>
      <geometry>
        <mesh filename="package://hmc_v2_hand_description/meshes/agibot_o12_t2_hand/right/right_ring_proximal.STL"/>
      </geometry>
      <material name="">
        <color rgba="1 1 1 1"/>
      </material>
    </visual>
    <collision>
      <origin rpy="0 0 0" xyz="0 0 0"/>
      <geometry>
        <mesh filename="package://hmc_v2_hand_description/meshes/agibot_o12_t2_hand/right/right_ring_proximal.STL"/>
      </geometry>
    </collision>
  </link>
  <joint name="right_ring_mcp_pitch" type="revolute">
    <origin rpy="0 0 0" xyz="0.0001598 -0.013573 0.11972"/>
    <parent link="right_hand_base_link"/>
    <child link="right_ring_proximal"/>
    <axis xyz="0 1 0"/>
    <limit effort="100" lower="0" upper="1.55" velocity="1"/>
  </joint>
  <link name="right_ring_middle">
    <inertial>
      <origin rpy="0 0 0" xyz="0.000940340714750308 -1.66667751162405E-05 0.0134216382614548"/>
      <mass value="0.0027077533496335"/>
      <inertia ixx="2.25767846748625E-07" ixy="4.61360531413437E-12" ixz="2.32301202429608E-09" iyy="1.61875511170868E-07" iyz="-9.05860342855209E-12" izz="1.17700137222491E-07"/>
    </inertial>
    <visual>
      <origin rpy="0 0 0" xyz="0 0 0"/>
      <geometry>
        <mesh filename="package://hmc_v2_hand_description/meshes/agibot_o12_t2_hand/right/right_ring_middle.STL"/>
      </geometry>
      <material name="">
        <color rgba="0 0 0 1"/>
      </material>
    </visual>
    <collision>
      <origin rpy="0 0 0" xyz="0 0 0"/>
      <geometry>
        <mesh filename="package://hmc_v2_hand_description/meshes/agibot_o12_t2_hand/right/right_ring_middle.STL"/>
      </geometry>
    </collision>
  </link>
  <joint name="right_ring_pip" type="revolute">
    <origin rpy="0 0 0" xyz="-0.0039295 0 0.03983"/>
    <parent link="right_ring_proximal"/>
    <child link="right_ring_middle"/>
    <axis xyz="0 1 0"/>
    <limit effort="100" lower="0" upper="1.439" velocity="1"/>
    <mimic joint="right_ring_mcp_pitch" multiplier="1" offset="0"/>
  </joint>
  <link name="right_ring_distal">
    <inertial>
      <origin rpy="0 0 0" xyz="-0.00679183129010172 -3.1051267307786E-05 0.00565592901618503"/>
      <mass value="0.00258259127175773"/>
      <inertia ixx="1.36530380213342E-07" ixy="9.44469863763946E-11" ixz="3.84707548646242E-08" iyy="1.36471612117152E-07" iyz="-3.22664356287902E-10" izz="9.47134934031493E-08"/>
    </inertial>
    <visual>
      <origin rpy="0 0 0" xyz="0 0 0"/>
      <geometry>
        <mesh filename="package://hmc_v2_hand_description/meshes/agibot_o12_t2_hand/right/right_ring_distal.STL"/>
      </geometry>
      <material name="">
        <color rgba="0.792156862745098 0.819607843137255 0.933333333333333 1"/>
      </material>
    </visual>
    <collision>
      <origin rpy="0 0 0" xyz="0 0 0"/>
      <geometry>
        <mesh filename="package://hmc_v2_hand_description/meshes/agibot_o12_t2_hand/right/right_ring_distal.STL"/>
      </geometry>
    </collision>
  </link>
  <joint name="right_ring_dip" type="revolute">
    <origin rpy="0 0 0" xyz="0.00601275714854613 0 0.0264415298059948"/>
    <parent link="right_ring_middle"/>
    <child link="right_ring_distal"/>
    <axis xyz="0 1 0"/>
    <limit effort="100" lower="0" upper="1.3257" velocity="1"/>
    <mimic joint="right_ring_mcp_pitch" multiplier="1" offset="0"/>
  </joint>
  <link name="right_ring_Virtual_Point">
    <inertial>
      <origin rpy="0 0 0" xyz="-1.13526896217131E-12 9.35964847292858E-13 5.27355936696949E-16"/>
      <mass value="5.23598775598299E-07"/>
      <inertia ixx="5.23598775598299E-14" ixy="1.58205846501508E-40" ixz="1.56203013032883E-40" iyy="5.23598775598299E-14" iyz="1.85037170770859E-30" izz="5.23598775598299E-14"/>
    </inertial>
    <visual>
      <origin rpy="0 0 0" xyz="0 0 0"/>
      <geometry>
        <mesh filename="package://hmc_v2_hand_description/meshes/agibot_o12_t2_hand/right/right_ring_Virtual_Point.STL"/>
      </geometry>
      <material name="">
        <color rgba="1 1 1 1"/>
      </material>
    </visual>
    <collision>
      <origin rpy="0 0 0" xyz="0 0 0"/>
      <geometry>
        <mesh filename="package://hmc_v2_hand_description/meshes/agibot_o12_t2_hand/right/right_ring_Virtual_Point.STL"/>
      </geometry>
    </collision>
  </link>
  <joint name="right_ring_Virtual_Point-none" type="fixed">
    <origin rpy="0 0 0" xyz="-0.01334 0 0.025167"/>
    <parent link="right_ring_distal"/>
    <child link="right_ring_Virtual_Point"/>
    <axis xyz="0 0 0"/>
  </joint>
  <link name="right_pinky_proximal">
    <inertial>
      <origin rpy="0 0 0" xyz="-0.0016180221168521 -2.08215074695289E-05 0.0212342179851402"/>
      <mass value="0.00477953323340541"/>
      <inertia ixx="5.43923274544673E-07" ixy="-8.48863445397533E-11" ixz="2.46894910332365E-08" iyy="5.41640168354855E-07" iyz="-2.52187730642466E-10" izz="1.7650175778066E-07"/>
    </inertial>
    <visual>
      <origin rpy="0 0 0" xyz="0 0 0"/>
      <geometry>
        <mesh filename="package://hmc_v2_hand_description/meshes/agibot_o12_t2_hand/right/right_pinky_proximal.STL"/>
      </geometry>
      <material name="">
        <color rgba="1 1 1 1"/>
      </material>
    </visual>
    <collision>
      <origin rpy="0 0 0" xyz="0 0 0"/>
      <geometry>
        <mesh filename="package://hmc_v2_hand_description/meshes/agibot_o12_t2_hand/right/right_pinky_proximal.STL"/>
      </geometry>
    </collision>
  </link>
  <joint name="right_pinky_mcp_pitch" type="revolute">
    <origin rpy="0 0 0" xyz="0.000159802654372855 -0.0336303181952511 0.11271621059493"/>
    <parent link="right_hand_base_link"/>
    <child link="right_pinky_proximal"/>
    <axis xyz="0 1 0"/>
    <limit effort="100" lower="0" upper="1.535" velocity="1"/>
  </joint>
  <link name="right_pinky_middle">
    <inertial>
      <origin rpy="0 0 0" xyz="0.000940340979638598 -1.66665156724755E-05 0.0134216381434371"/>
      <mass value="0.00270775345292578"/>
      <inertia ixx="2.25767855959524E-07" ixy="4.61316580602277E-12" ixz="2.32301150942084E-09" iyy="1.61875516933061E-07" iyz="-9.05509549786009E-12" izz="1.17700140839825E-07"/>
    </inertial>
    <visual>
      <origin rpy="0 0 0" xyz="0 0 0"/>
      <geometry>
        <mesh filename="package://hmc_v2_hand_description/meshes/agibot_o12_t2_hand/right/right_pinky_middle.STL"/>
      </geometry>
      <material name="">
        <color rgba="0 0 0 1"/>
      </material>
    </visual>
    <collision>
      <origin rpy="0 0 0" xyz="0 0 0"/>
      <geometry>
        <mesh filename="package://hmc_v2_hand_description/meshes/agibot_o12_t2_hand/right/right_pinky_middle.STL"/>
      </geometry>
    </collision>
  </link>
  <joint name="right_pinky_pip" type="revolute">
    <origin rpy="0 0 0" xyz="-0.00392950397727024 0 0.0398303439412377"/>
    <parent link="right_pinky_proximal"/>
    <child link="right_pinky_middle"/>
    <axis xyz="0 1 0"/>
    <limit effort="100" lower="0" upper="1.413" velocity="1"/>
    <mimic joint="right_pinky_mcp_pitch" multiplier="1" offset="0"/>
  </joint>
  <link name="right_pinky_distal">
    <inertial>
      <origin rpy="0 0 0" xyz="-0.00679190409450586 -3.10511081597076E-05 0.00565584201307923"/>
      <mass value="0.00258259141809727"/>
      <inertia ixx="1.36529403216541E-07" ixy="9.44507918542087E-11" ixz="3.84712982116646E-08" iyy="1.36471628325979E-07" iyz="-3.22662637208023E-10" izz="9.47144825482917E-08"/>
    </inertial>
    <visual>
      <origin rpy="0 0 0" xyz="0 0 0"/>
      <geometry>
        <mesh filename="package://hmc_v2_hand_description/meshes/agibot_o12_t2_hand/right/right_pinky_distal.STL"/>
      </geometry>
      <material name="">
        <color rgba="0.792156862745098 0.819607843137255 0.933333333333333 1"/>
      </material>
    </visual>
    <collision>
      <origin rpy="0 0 0" xyz="0 0 0"/>
      <geometry>
        <mesh filename="package://hmc_v2_hand_description/meshes/agibot_o12_t2_hand/right/right_pinky_distal.STL"/>
      </geometry>
    </collision>
  </link>
  <joint name="right_pinky_dip" type="revolute">
    <origin rpy="0 0 0" xyz="0.00601270306428537 0 0.0264416319816371"/>
    <parent link="right_pinky_middle"/>
    <child link="right_pinky_distal"/>
    <axis xyz="0 1 0"/>
    <limit effort="100" lower="0" upper="1.325" velocity="1"/>
    <mimic joint="right_pinky_mcp_pitch" multiplier="1" offset="0"/>
  </joint>
  <link name="right_pinky_Virtual_Point">
    <inertial>
      <origin rpy="0 0 0" xyz="-2.83552521740393E-12 9.35987398698046E-13 8.32667268468867E-17"/>
      <mass value="5.23598775598299E-07"/>
      <inertia ixx="5.23598775598299E-14" ixy="3.70623385375214E-40" ixz="1.56278809626202E-40" iyy="5.23598775598299E-14" iyz="1.85037170770859E-30" izz="5.23598775598299E-14"/>
    </inertial>
    <visual>
      <origin rpy="0 0 0" xyz="0 0 0"/>
      <geometry>
        <mesh filename="package://hmc_v2_hand_description/meshes/agibot_o12_t2_hand/right/right_pinky_Virtual_Point.STL"/>
      </geometry>
      <material name="">
        <color rgba="1 1 1 1"/>
      </material>
    </visual>
    <collision>
      <origin rpy="0 0 0" xyz="0 0 0"/>
      <geometry>
        <mesh filename="package://hmc_v2_hand_description/meshes/agibot_o12_t2_hand/right/right_pinky_Virtual_Point.STL"/>
      </geometry>
    </collision>
  </link>
  <joint name="right_pinky_Virtual_Point-none" type="fixed">
    <origin rpy="0 0 0" xyz="-0.0133404537520391 0 0.0251663685805378"/>
    <parent link="right_pinky_distal"/>
    <child link="right_pinky_Virtual_Point"/>
    <axis xyz="0 0 0"/>
  </joint>
  <joint name="body_base_joint" type="fixed">
    <parent link="base_link"/>
    <child link="body_base_link"/>
    <origin rpy="0 0 0" xyz="0.01 0 0.295"/>
  </joint>
  <joint name="left_hand_base_joint" type="fixed">
    <parent link="left_tool_base_link"/>
    <child link="left_hand_base_link"/>
    <origin rpy="0 0 0" xyz="0 0 0"/>
  </joint>
  <joint name="right_hand_base_joint" type="fixed">
    <parent link="right_tool_base_link"/>
    <child link="right_hand_base_link"/>
    <origin rpy="0 0 0" xyz="0 0 0"/>
  </joint>
</robot>
